Workbook

Sheet Шаблон
A1: 23 неделя с 25.05 по 31.05.2026
A2: ОРС | M2: Факт
A3: Ростов | B3: Осталось собрать на 25.05 | C3: Факт с 25.05-31.05.2026 | D3: Осталось собрать на 01.06.2026 | K3: Менеджеры | L3: Счета Юр.услуги | M3: Счета Вступления | N3: Сбор Юр.услуги | O3: Кол-во вступлений
A4: Начислено за квартал | K4: Наташа
A5: Переплата за квартал | K5: Ира
A6: План сбора за квартал | K6: Таня
A7: Долг действующие | K7: Роман
A8: Долг исключенные | K8: Давид
A9: Сбор ЧВ по вступившим в этом квартале | K9: Итого:
A10: Переплата
A11: Сумма ЧВ у пристовов | M11: План
A12: Сумма ЧВ в суде | K12: Менеджеры | L12: Счета Юр.услуги | M12: Счета Вступления | N12: Сбор Юр.услуги | O12: Кол-во вступлений
A13: Поступление от судебной деятельности | K13: Наташа
A14: Итого: | K14: Ира
K15: Таня
A16: Бизнес-групп | K16: Роман
A17: Наименование | B17: План на | C17: 01.06.2026 | D17: Факт на | E17: 25.05-31.05.2026 | F17: Поступление на | G17: 25.07-25.07.2026 | H17: План на | I17: 23.07.2026 | K17: Давид
B18: Колличество | C18: Сумма | D18: Колличество | E18: Сумма | F18: Колличество | G18: Сумма | H18: Колличество | I18: Сумма | K18: Итого:
A19: Выставленные счета на юр. Услугам
A20: Выставленные счета на прохождение экзамена
A21: Ранее выставленные счета на юр. Услуги
A22: Ранее выставленные счета на экзамен
A23: Счета на вступления
A24: Вступления
A25: Итог:
A27: Юрлидер
A28: Наименование | B28: План на | C28: 01.06.2026 | D28: Факт на | E28: 25.05-31.05.2026 | F28: Поступление на | G28: 25.07-25.07.2026 | H28: План на | I28: 23.07.2026
B29: Колличество | C29: Сумма | D29: Колличество | E29: Сумма | F29: Колличество | G29: Сумма | H29: Колличество | I29: Сумма
A30: Выставленные счета на юр. Услугам
A31: Ранее выставленные счета на юр. Услуги
A32: Счета на вступления
A33: Вступления
A34: Итог:
A36: Юридический отдел
A37: Наименование | B37: Факт с 25.05-31.05.2026 | C37: Факт с 25.05-31.05.20262 | D37: Факт с 25.05-31.05.20263
A38: Сумма ЧВ у приставов действ
A39: Сумма ЧВ в суде действ
A40: Сумма ЧВ у приставов искл
A41: Сумма ЧВ в суде искл
A42: Поступления по СД искл
...

Sheet Злобин Андрей
A1: Ростов
A2: № | B2: Наименование | C2: Осталось собрать на 01.01 | D2: Факт с 01.01 по 18.01 | E2: осталось собрать на 18.01
A3: 1 | B3: Членские взносы | C3: 19534860 | D3: 4815200 | E3: =C3-D3 -> 14719660
A4: 2 | B4: Долг действующие | C4: 14803324 | D4: 155500 | E4: =C4-D4 -> 14647824
A5: 3 | B5: Долг исключенные | C5: 10075715 | D5: 254300 | E5: =C5-D5 -> 9821415
A6: 4 | B6: переплата | D6: 329800
A7: 5 | B7: возврат ошибочно переведенных
B8: Итого: | C8: 44413899 | D8: 5554800 | E8: =SUM(E3:E5) -> 39188899

Sheet 3 неделя
A2: 3 неделя с 01.01 по 18.01.2026
A3: Ростов | H3: Факт
A4: Наименование | B4: Осталось собрать на 01.01 | C4: Факт с 01.01 по 18.01 | D4: осталось собрать на 19.01 | E4: План | I4: Счета Юр.услуги | J4: Счета Вступления | K4: Сбор Юр.услуги | L4: Кол-во вступлений
A5: Членские взносы | B5: 19534860 | C5: 5732150 | D5: =B5-C5 -> 13802710 | H5: Наташа | I5: 13 | J5: 1 | K5: 400000 | L5: 1
A6: Долг действующие | B6: 14803324 | C6: 155500 | D6: =B6-C6 -> 14647824 | H6: Ира | I6: 2 | J6: 3 | K6: 205000 | L6: 0
A7: Долг исключенные | B7: 10075715 | C7: 254300 | D7: =B7-C7 -> 9821415 | H7: Таня | I7: 2 | J7: 0 | K7: 0 | L7: 0
A8: переплата | C8: 336000 | H8: Роман | I8: 1 | J8: 0 | K8: 35000 | L8: 0
A9: Итого: | B9: =SUM(B5:B8) -> 44413899 | C9: =SUM(C5:C8) -> 6477950 | D9: =SUM(D5:D7) -> 38271949 | H9: Давид | I9: 0 | J9: 0 | K9: 0 | L9: 0
H10: Итого: | I10: =SUBTOTAL(109,I5:I9) -> 18 | J10: =SUBTOTAL(109,J5:J9) -> 4 | K10: =SUM(K5:K9) -> 640000 | L10: =SUM(L5:L9) -> 1
A11: БГ
A12: Наименование | B12: План на 01.01 | C12: Факт с 01.01 по 18.01 | D12: План на 19.01 | H12: План
A13: Счета на чв | B13: 0 | C13: 900 | D13: 0 | I13: Счета Юр.услуги | J13: Счета Вступления | K13: Сбор Юр.услуги | L13: Кол-во вступлений
A14: Счета на юридические услуги. | B14: 0 | C14: 1 | D14: 10 | H14: Наташа | I14: 3 | J14: 0 | K14: 100000 | L14: 0
A15: Поступления по юр. Услугам. | B15: 0 | C15: 40000 | D15: 500000 | H15: Ира | I15: 1 | J15: 1 | K15: 50000 | L15: 3
A16: Счета на прохождение экзамена | B16: 0 | C16: 1 | D16: 1 | H16: Таня | I16: 1 | J16: 1 | K16: 50000 | L16: 1
A17: Счета на вступления. | B17: 0 | C17: 4 | D17: 5 | H17: Роман | I17: 0 | J17: 0 | K17: 50000 | L17: 0
A18: Вступления. | B18: 0 | C18: 4 | D18: 5 | H18: Давид | I18: 0 | J18: 0 | K18: 0 | L18: 0
A19: Получение исп. Листов | B19: 0 | C19: 5 | D19: 5 | H19: Итого: | I19: =SUM(I14:I18) -> 5 | J19: =SUM(J14:J18) -> 2 | K19: =SUM(K14:K18) -> 250000 | L19: =SUM(L14:L18) -> 4
A20: Подача в суд по ч\в. | B20: 0 | C20: 0 | D20: 0
A21: Сбор по исполнительным листам | B21: 0 | C21: 178300 | D21: 6420000
A22: Сбор за экзамен | B22: 0 | C22: 0 | D22: 26000
A23: Итого: | C23: =C15+C21+C22 -> 218300
A25: Юрлидер
A26: Наименование | B26: План на 01.01 | C26: Факт с 01.01 по 18.01 | D26: План на 19.01
A27: Счета на юр услуги. | B27: 0 | C27: 18 | D27: 5
A28: Счета на вступления | B28: 0 | C28: 4 | D28: 2
A29: Сбор юр услуги | B29: 0 | C29: 640000 | D29: 250000
A30: Вступления | B30: 0 | C30: 1 | D30: 4

Sheet 4 неделя
A1: 4 неделя с 19.01 по 23.01.2026
A2: Ростов | I2: Факт
A3: Наименование | B3: Осталось собрать на 19.01 | C3: Факт с 19.01 по 23.01 | D3: осталось собрать на 23.01 | E3: План | H3: Счета Юр.услуги | I3: Счета Вступления | J3: Сбор Юр.услуги | K3: Кол-во вступлений
A4: Членские взносы | B4: 13802710 | C4: 1405500 | D4: =Таблица8[[#This Row],[Осталось собрать на 19.01]]-Таблица8[[#This Row],[Факт с 19.01 по 23.01]] -> 12397210 | G4: Наташа | H4: 7 | I4: 1 | J4: 345000 | K4: 0
A5: Долг действующие | B5: 14647824 | C5: 349500 | D5: =Таблица8[[#This Row],[Осталось собрать на 19.01]]-Таблица8[[#This Row],[Факт с 19.01 по 23.01]] -> 14298324 | G5: Ира | H5: 10 | I5: 0 | J5: 495000 | K5: 2
A6: Долг исключенные | B6: 9821415 | C6: 189967.17 | D6: =Таблица8[[#This Row],[Осталось собрать на 19.01]]-Таблица8[[#This Row],[Факт с 19.01 по 23.01]] -> 9631447.8 | G6: Таня | H6: 7 | I6: 1 | J6: 25000 | K6: 0
A7: переплата | C7: 180000 | G7: Роман | H7: 0 | I7: 0 | J7: 0 | K7: 0
A8: Итого: | B8: =SUM(B4:B7) -> 38271949 | C8: =SUM(C4:C7) -> 2124967.2 | D8: =SUM(D4:D6) -> 36326982 | G8: Давид | H8: 14 | I8: 1 | J8: 170000 | K8: 1
G9: Итого: | H9: =SUM(H4:H8) -> 38 | I9: =SUBTOTAL(109,I4:I8) -> 3 | J9: =SUM(J4:J8) -> 1035000 | K9: =SUM(K4:K8) -> 3
A10: БГ
A11: Наименование | B11: План на 19.01 | C11: Факт с 19.01 по 23.01 | D11: План на 23.01 | I11: План
A12: Счета на чв | B12: 0 | C12: 900 | D12: 0 | H12: Счета Юр.услуги | I12: Счета Вступления | J12: Сбор Юр.услуги | K12: Кол-во вступлений
A13: Счета на юридические услуги. | B13: 10 | C13: 8 | D13: 12 | G13: Наташа | H13: 5 | I13: 1 | J13: 100000 | K13: 1
A14: Поступления по юр. Услугам. | B14: 500000 | C14: 415000 | D14: 600000 | G14: Ира | H14: 1 | I14: 1 | J14: 50000 | K14: 1
A15: Счета на прохождение экзамена | B15: 1 | C15: 1 | D15: 1 | G15: Таня | H15: 5 | I15: 1 | J15: 100000 | K15: 1
A16: Счета на вступления. | B16: 5 | C16: 4 | D16: 5 | G16: Роман | H16: 2 | I16: 0 | J16: 70000 | K16: 0
A17: Вступления. | B17: 5 | C17: 4 | D17: 5 | G17: Давид | H17: 1 | I17: 0 | J17: 100000 | K17: 0
A18: Получение исп. Листов | B18: 5 | C18: 5 | D18: 0 | G18: Итого: | H18: =SUM(H13:H17) -> 14 | I18: =SUM(I13:I17) -> 3 | J18: =SUM(J13:J17) -> 420000 | K18: =SUM(K13:K17) -> 3
A19: Подача в суд по ч\в. | B19: 0 | C19: 0 | D19: 0
A20: Сбор по исполнительным листам | B20: 3420000 | C20: 346967 | D20: 6049000
A21: Сбор за экзамен | B21: 26000 | C21: 0 | D21: 26000
A22: Итого: | C22: =C14+C20+C21 -> 761967
A24: Юрлидер
A25: Наименование | B25: План на 19.01 | C25: Факт с 19.01 по 23.01 | D25: План на 23.01
A26: Счета на юр услуги. | B26: 5 | C26: 38 | D26: 14
A27: Счета на вступления | B27: 2 | C27: 3 | D27: 3
A28: Сбор юр услуги | B28: 250000 | C28: 1035000 | D28: 420000
A29: Вступления | B29: 4 | C29: 3 | D29: 3

Sheet 5 неделя
A1: 4 неделя с 26.01 по 30.01.2026
A2: Ростов | I2: Факт
A3: Наименование | B3: Осталось собрать на 26.01 | C3: Факт с 26.01 по 30.01 | D3: осталось собрать на 30.01 | E3: План | H3: Счета Юр.услуги | I3: Счета Вступления | J3: Сбор Юр.услуги | K3: Кол-во вступлений
A4: Членские взносы | B4: 12397210 | C4: 564500 | D4: =Таблица814[[#This Row],[Осталось собрать на 26.01]]-Таблица814[[#This Row],[Факт с 26.01 по 30.01]] -> 11832710 | G4: Наташа | H4: 9 | I4: 0 | J4: 160000 | K4: 0
A5: Долг действующие | B5: 14298324 | C5: 203000 | D5: =Таблица814[[#This Row],[Осталось собрать на 26.01]]-Таблица814[[#This Row],[Факт с 26.01 по 30.01]] -> 14095324 | G5: Ира | H5: 2 | I5: 1 | J5: 165000 | K5: 0
A6: Долг исключенные | B6: 9631448 | C6: 203000 | D6: =Таблица814[[#This Row],[Осталось собрать на 26.01]]-Таблица814[[#This Row],[Факт с 26.01 по 30.01]] -> 9428448 | G6: Таня | H6: 3 | I6: 0 | J6: 40000 | K6: 0
A7: переплата | C7: 120000 | G7: Роман | H7: 3 | I7: 0 | J7: 45000 | K7: 0
A8: Итого: | B8: =SUM(B4:B7) -> 36326982 | C8: =SUM(C4:C7) -> 1090500 | D8: =SUM(D4:D6) -> 35356482 | G8: Давид | H8: 1 | I8: 1 | J8: 47000 | K8: 0
G9: Итого: | H9: =SUM(H4:H8) -> 18 | I9: =SUBTOTAL(109,I4:I8) -> 2 | J9: =SUM(J4:J8) -> 457000 | K9: =SUM(K4:K8) -> 0
A10: БГ
A11: Наименование | B11: План на 26.01 | C11: Факт с 26.01 по 30.01 | D11: План на 30.01 | I11: План
A12: Счета на чв | B12: 0 | C12: 0 | D12: 0 | H12: Счета Юр.услуги | I12: Счета Вступления | J12: Сбор Юр.услуги | K12: Кол-во вступлений
A13: Счета на юридические услуги. | B13: 12 | C13: 7 | D13: 6 | G13: Наташа | H13: 5 | I13: 0 | J13: 150000 | K13: 0
A14: Поступления по юр. Услугам. | B14: 600000 | C14: 370000 | D14: 300000 | G14: Ира | H14: 1 | I14: 1 | J14: 50000 | K14: 1
A15: Счета на прохождение экзамена | B15: 1 | C15: 0 | D15: 1 | G15: Таня | H15: 5 | I15: 1 | J15: 50000 | K15: 1
A16: Счета на вступления. | B16: 5 | C16: 2 | D16: 0 | G16: Роман | H16: 2 | I16: 0 | J16: 120000 | K16: 0
A17: Вступления. | B17: 5 | C17: 2 | D17: 5 | G17: Давид | H17: 1 | I17: 1 | J17: 100000 | K17: 1
A18: Получение исп. Листов | B18: 0 | C18: 0 | D18: 4 | G18: Итого: | H18: =SUM(H13:H17) -> 14 | I18: =SUM(I13:I17) -> 3 | J18: =SUM(J13:J17) -> 470000 | K18: =SUM(K13:K17) -> 3
A19: Подача в суд по ч\в. | B19: 0 | C19: 0 | D19: 0
A20: Сбор по исполнительным листам | B20: 6049000 | C20: 317000 | D20: 6260000
A21: Сбор за экзамен | B21: 26000 | C21: 0 | D21: 26000
A22: Итого: | C22: =C14+C20+C21 -> 687000
A24: Юрлидер
A25: Наименование | B25: План на 26.01 | C25: Факт с 26.01 по 30.01 | D25: План на 30.01
A26: Счета на юр услуги. | B26: 14 | C26: 18 | D26: 14
A27: Счета на вступления | B27: 3 | C27: 2 | D27: 3
A28: Сбор юр услуги | B28: 420 | C28: 457000 | D28: 470000
A29: Вступления | B29: 3 | C29: 0 | D29: 3

Sheet 6 неделя
A2: 6 неделя с 02.02 по 08.02.2026
A3: Ростов | I3: Факт
A4: Наименование | B4: Осталось собрать на 30.01 | C4: Факт с 02.02 по 08.02 | D4: План на 09.02 | E4: План | H4: Счета Юр.услуги | I4: Счета Вступления | J4: Сбор Юр.услуги | K4: Кол-во вступлений
A5: Членские взносы | B5: ='5 неделя'!D4 -> 11832710 | C5: 245000 | D5: =Таблица81419[[#This Row],[Осталось собрать на 30.01]]-Таблица81419[[#This Row],[Факт с 02.02 по 08.02]] -> 11587710 | G5: Наташа
A6: Долг действующие | B6: ='5 неделя'!D5 -> 14095324 | C6: 50000 | D6: =Таблица81419[[#This Row],[Осталось собрать на 30.01]]-Таблица81419[[#This Row],[Факт с 02.02 по 08.02]] -> 14045324 | G6: Ира | H6: 3 | I6: 2 | J6: 255000 | K6: 0
A7: Долг исключенные | B7: ='5 неделя'!D6 -> 9428448 | C7: 0 | D7: =Таблица81419[[#This Row],[Осталось собрать на 30.01]]-Таблица81419[[#This Row],[Факт с 02.02 по 08.02]] -> 9428448 | G7: Таня | H7: 3 | I7: 2 | J7: 175000 | K7: 1
A8: переплата | B8: ='5 неделя'!D7 -> 0 | C8: 45000 | G8: Роман | H8: 3 | I8: 0 | J8: 60000 | K8: 0
A9: Итого: | B9: ='5 неделя'!D8 -> 35356482 | C9: =SUM(C5:C8) -> 340000 | D9: =SUM(D5:D7) -> 35061482 | G9: Давид | H9: 3 | I9: 1 | J9: 0 | K9: 0
G10: Итого: | H10: =SUM(H5:H9) -> 12 | I10: =SUM(I5:I9) -> 5 | J10: =SUM(J5:J9) -> 490000 | K10: =SUM(K5:K9) -> 1
A11: БГ
A12: Наименование | B12: План на 30.01 | C12: Факт с 02.02 по 08.02 | D12: План на 09.02 | I12: План
A13: Счета на чв | B13: 0 | C13: 0 | D13: 0 | H13: Счета Юр.услуги | I13: Счета Вступления | J13: Сбор Юр.услуги | K13: Кол-во вступлений
A14: Счета на юридические услуги. | B14: 6 | C14: 4 | D14: 5 | G14: Наташа
A15: Поступления по юр. Услугам. | B15: 300000 | C15: 175000 | D15: 250000 | G15: Ира | H15: 1 | I15: 1 | J15: 50000 | K15: 2
A16: Счета на прохождение экзамена | B16: 1 | C16: 5 | D16: 6 | G16: Таня | H16: 1 | I16: 1 | J16: 50000 | K16: 1
A17: Счета на вступления. | B17: 0 | C17: 2 | D17: 5 | G17: Роман | H17: 1 | I17: 0 | J17: 100000 | K17: 0
A18: Вступления. | B18: 5 | C18: 2 | D18: 5 | G18: Давид | H18: 1 | I18: 0 | J18: 75000 | K18: 0
A19: Получение исп. Листов | B19: 4 | C19: 4 | D19: 4 | G19: Итого: | H19: =SUM(H15:H18) -> 4 | I19: =SUM(I15:I18) -> 2 | J19: =SUM(J15:J18) -> 275000 | K19: =SUM(K15:K18) -> 3
A20: Подача в суд по ч\в. | B20: 0 | C20: 0 | D20: 0
A21: Сбор по исполнительным листам | B21: 6260000 | C21: 0 | D21: 6360000
A22: Сбор за экзамен | B22: 26000 | C22: 0 | D22: 0
A23: Итого: | C23: =C15+C21+C22 -> 175000
A25: Юрлидер
A26: Наименование | B26: План на 30.01 | C26: Факт с 02.02 по 08.02 | D26: План на 09.02
A27: Счета на юр услуги. | B27: 14 | C27: 12 | D27: 4
A28: Счета на вступления | B28: 3 | C28: 5 | D28: 2
A29: Сбор юр услуги | B29: 470000 | C29: 490000 | D29: 275000
A30: Вступления | B30: 3 | C30: 1 | D30: 3

Sheet 7 неделя
A2: 7 неделя с 09.02 по 15.02.2026
A3: Ростов | I3: Факт
A4: Наименование | B4: Осталось собрать на 09.02 | C4: Факт с 09.02 по 15.02 | D4: План на 16.02 | E4: План | H4: Счета Юр.услуги | I4: Счета Вступления | J4: Сбор Юр.услуги | K4: Кол-во вступлений
A5: Членские взносы | B5: =Таблица81419[[#This Row],[План на 09.02]] -> 11587710 | C5: 380000 | D5: =Таблица814192423[[#This Row],[Осталось собрать на 09.02]]-Таблица814192423[[#This Row],[Факт с 09.02 по 15.02]] -> 11207710 | G5: Наташа | H5: 3 | I5: 0 | J5: 0 | K5: 0
A6: Долг действующие | B6: =Таблица81419[[#This Row],[План на 09.02]] -> 14045324 | C6: 245000 | D6: =Таблица814192423[[#This Row],[Осталось собрать на 09.02]]-Таблица814192423[[#This Row],[Факт с 09.02 по 15.02]] -> 13800324 | G6: Ира | H6: 2 | I6: 2 | J6: 150000 | K6: 1
A7: Долг исключенные | B7: =Таблица81419[[#This Row],[План на 09.02]] -> 9428448 | C7: 96000 | D7: =Таблица814192423[[#This Row],[Осталось собрать на 09.02]]-Таблица814192423[[#This Row],[Факт с 09.02 по 15.02]] -> 9332448 | G7: Таня | H7: 3 | I7: 1 | J7: 40000 | K7: 0
A8: переплата | B8: =Таблица81419[[#This Row],[План на 09.02]] -> 0 | C8: 2452000 | G8: Роман | H8: 3 | I8: 0 | J8: 0 | K8: 0
A9: Итого: | B9: =Таблица81419[[#This Row],[План на 09.02]] -> 35061482 | C9: =SUM(C5:C8) -> 3173000 | D9: =SUM(D5:D7) -> 34340482 | G9: Давид | H9: 1 | I9: 0 | J9: 55000 | K9: 0
G10: Итого: | H10: =SUM(H5:H9) -> 12 | I10: =SUM(I5:I9) -> 3 | J10: =SUM(J5:J9) -> 245000 | K10: =SUM(K5:K9) -> 1
A11: БГ
A12: Наименование | B12: Осталось собрать на 09.02 | C12: Факт с 09.02 по 15.02 | D12: План на 16.02 | I12: План
A13: Счета на чв | B13: 0 | C13: 0 | D13: 0 | H13: Счета Юр.услуги | I13: Счета Вступления | J13: Сбор Юр.услуги | K13: Кол-во вступлений
A14: Счета на юридические услуги. | B14: 5 | C14: 2 | D14: 10 | G14: Наташа
A15: Поступления по юр. Услугам. | B15: 250000 | C15: 100000 | D15: 500000 | G15: Ира
A16: Счета на прохождение экзамена | B16: 6 | C16: 3 | D16: 5 | G16: Таня
A17: Счета на вступления. | B17: 5 | C17: 5 | D17: 5 | G17: Роман
A18: Вступления. | B18: 5 | C18: 5 | D18: 5 | G18: Давид
A19: Получение исп. Листов | B19: 4 | C19: 4 | D19: 3 | G19: Итого: | H19: =SUM(H14:H18) -> 0 | I19: =SUM(I14:I18) -> 0 | J19: =SUM(J14:J18) -> 0 | K19: =SUM(K14:K18) -> 0
A20: Подача в суд по ч\в. | B20: 0 | C20: 0 | D20: 0
A21: Сбор по исполнительным листам | B21: 6360000 | C21: 295144 | D21: 6150000
A22: Сбор за экзамен | B22: 0 | C22: 0 | D22: 0
A23: Итого: | C23: =C15+C21+C22 -> 395144
A25: Юрлидер
A26: Наименование | B26: Осталось собрать на 09.02 | C26: Факт с 09.02 по 15.02 | D26: План на 16.02
A27: Счета на юр услуги. | B27: 4 | C27: 12 | D27: 25
A28: Счета на вступления | B28: 2 | C28: 3 | D28: 2
A29: Сбор юр услуги | B29: 275000 | C29: 245000 | D29: 460000
A30: Вступления | B30: 3 | C30: 1 | D30: 2

Sheet 8 неделя
A2: 8 неделя с 16.02 по 22.02.2026
A3: Ростов | I3: Факт
A4: Наименование | B4: Осталось собрать на 16.02 | C4: Факт с 16.02 по 22.02 | D4: План на 23.02 | E4: План | H4: Счета Юр.услуги | I4: Счета Вступления | J4: Сбор Юр.услуги | K4: Кол-во вступлений
A5: Членские взносы | B5: =Таблица814192423[[#This Row],[План на 16.02]] -> 11207710 | C5: 568000 | D5: =Таблица81419242318[[#This Row],[Осталось собрать на 16.02]]-Таблица81419242318[[#This Row],[Факт с 16.02 по 22.02]] -> 10639710 | G5: Наташа | H5: 10 | I5: 3 | J5: 530000 | K5: 0
A6: Долг действующие | B6: =Таблица814192423[[#This Row],[План на 16.02]] -> 13800324 | C6: 90000 | D6: =Таблица81419242318[[#This Row],[Осталось собрать на 16.02]]-Таблица81419242318[[#This Row],[Факт с 16.02 по 22.02]] -> 13710324 | G6: Ира | H6: 10 | I6: 1 | J6: 340000 | K6: 2
A7: Долг исключенные | B7: =Таблица814192423[[#This Row],[План на 16.02]] -> 9332448 | C7: 0 | D7: =Таблица81419242318[[#This Row],[Осталось собрать на 16.02]]-Таблица81419242318[[#This Row],[Факт с 16.02 по 22.02]] -> 9332448 | G7: Таня | H7: 3 | I7: 1 | J7: 50000 | K7: 0
A8: переплата | B8: =Таблица814192423[[#This Row],[План на 16.02]] -> 0 | C8: 185000 | G8: Роман | H8: 0 | I8: 0 | J8: 0 | K8: 0
A9: Итого: | B9: =Таблица814192423[[#This Row],[План на 16.02]] -> 34340482 | C9: =SUM(C5:C8) -> 843000 | D9: =SUM(D5:D7) -> 33682482 | G9: Давид | H9: 8 | I9: 0 | J9: 65000 | K9: 0
G10: Итого: | H10: =SUM(H5:H9) -> 31 | I10: =SUM(I5:I9) -> 5 | J10: =SUM(J5:J9) -> 985000 | K10: =SUM(K5:K9) -> 2
A12: БГ | I12: План
A13: Наименование | B13: Осталось собрать на 16.02 | C13: Факт с 16.02 по 22.02 | D13: План на 23.02 | H13: Счета Юр.услуги | I13: Счета Вступления | J13: Сбор Юр.услуги | K13: Кол-во вступлений
A14: Счета на чв | B14: 0 | C14: 0 | D14: 0 | G14: Наташа | H14: 5 | I14: 1 | J14: 100000 | K14: 1
A15: Счета на юридические услуги. | B15: 10 | C15: 13 | D15: 10 | G15: Ира | H15: 1 | I15: 1 | J15: 50000 | K15: 1
A16: Поступления по юр. Услугам. | B16: 500000 | C16: 675000 | D16: 500000 | G16: Таня | H16: 4 | I16: =SUM(I11:I15) -> 2 | J16: 100000 | K16: 2
A17: Счета на прохождение экзамена | B17: 5 | C17: 1 | D17: 2 | G17: Роман | H17: 0 | I17: 0 | J17: 0 | K17: 0
A18: Счета на вступления. | B18: 5 | C18: 4 | D18: 5 | G18: Давид | H18: 1 | I18: 0 | J18: 30000 | K18: 1
A19: Вступления. | B19: 5 | C19: 4 | D19: 5 | G19: Итого: | H19: =SUM(H14:H18) -> 11 | I19: =SUM(I14:I18) -> 4 | J19: =SUM(J14:J18) -> 280000 | K19: =SUM(K14:K18) -> 5
A20: Получение исп. Листов | B20: 3 | C20: 3 | D20: 0
A21: Подача в суд по ч\в. | B21: 0 | C21: 0 | D21: 0
A22: Сбор по исполнительным листам | B22: 6150000 | C22: 196000 | D22: 6250000
A23: Сбор за экзамен | B23: 0 | C23: 0 | D23: 0
A24: Итого: | C24: =C16+C22+C23 -> 871000
A26: Юрлидер
A27: Наименование | B27: Осталось собрать на 16.02 | C27: Факт с 16.02 по 22.02 | D27: План на 23.02
A28: Счета на юр услуги. | B28: 25 | C28: 31 | D28: 11
A29: Счета на вступления | B29: 2 | C29: 5 | D29: 4
A30: Сбор юр услуги | B30: 460000 | C30: 985000 | D30: 280000
A31: Вступления | B31: 2 | C31: 2 | D31: 5

Sheet 9 неделя
A2: 9 неделя с 23.02 по 01.03.2026
A3: Ростов | I3: Факт
A4: Наименование | B4: Осталось собрать на 23.02 | C4: Факт с 23.02 по 01.03 | D4: План на 02.03 | E4: План | H4: Счета Юр.услуги | I4: Счета Вступления | J4: Сбор Юр.услуги | K4: Кол-во вступлений
A5: Членские взносы | B5: =Таблица81419242318[[#This Row],[План на 23.02]] -> 10639710 | C5: 695000 | D5: =Таблица81419242934[[#This Row],[Осталось собрать на 23.02]]-Таблица81419242934[[#This Row],[Факт с 23.02 по 01.03]] -> 9944710 | G5: Наташа | H5: 5 | I5: 1 | J5: 235000 | K5: 1
A6: Долг действующие | B6: =Таблица81419242318[[#This Row],[План на 23.02]] -> 13710324 | C6: 124000 | D6: =Таблица81419242934[[#This Row],[Осталось собрать на 23.02]]-Таблица81419242934[[#This Row],[Факт с 23.02 по 01.03]] -> 13586324 | G6: Ира | H6: 10 | I6: 1 | J6: 125000 | K6: 2
A7: Долг исключенные | B7: =Таблица81419242318[[#This Row],[План на 23.02]] -> 9332448 | C7: 47702 | D7: =Таблица81419242934[[#This Row],[Осталось собрать на 23.02]]-Таблица81419242934[[#This Row],[Факт с 23.02 по 01.03]] -> 9284746 | G7: Таня | H7: 4 | I7: 1 | J7: 85000 | K7: 3
A8: переплата | C8: 279495 | G8: Роман | H8: 0 | I8: 0 | J8: 0 | K8: 0
A9: Итого: | B9: =SUM(B5:B8) -> 33682482 | C9: =SUM(C5:C8) -> 1146197 | D9: =SUM(D5:D7) -> 32815780 | G9: Давид | H9: 1 | I9: 0 | J9: 55000 | K9: 1
G10: Итого: | H10: =SUM(H5:H9) -> 20 | I10: =SUM(I5:I9) -> 3 | J10: =SUM(J5:J9) -> 500000 | K10: =SUM(K5:K9) -> 7
A11: БГ
A12: Наименование | B12: Осталось собрать на 23.02 | C12: Факт с 23.02 по 01.03 | D12: План на 02.03 | I12: План
A13: Счета на чв | B13: 0 | C13: 0 | D13: 0 | H13: Счета Юр.услуги | I13: Счета Вступления | J13: Сбор Юр.услуги | K13: Кол-во вступлений
A14: Счета на юридические услуги. | B14: 10 | C14: 11 | D14: 4 | G14: Наташа | H14: 1 | I14: 1 | J14: 50000 | K14: 1
A15: Поступления по юр. Услугам. | B15: 500000 | C15: 560000 | D15: 200000 | G15: Ира | H15: 1 | I15: 1 | J15: 50000 | K15: 1
A16: Счета на прохождение экзамена | B16: 2 | C16: 3 | D16: 4 | G16: Таня | H16: 1 | I16: 1 | J16: 50000 | K16: 1
A17: Счета на вступления. | B17: 5 | C17: 8 | D17: 6 | G17: Роман | H17: 2 | I17: 0 | J17: 70000 | K17: 0
A18: Вступления. | B18: 5 | C18: 8 | D18: 6 | G18: Давид | H18: 1 | I18: 0 | J18: 60000 | K18: 0
A19: Получение исп. Листов | B19: 0 | C19: 0 | D19: 1 | G19: Итого: | H19: =SUM(H14:H18) -> 6 | I19: =SUM(I14:I18) -> 3 | J19: =SUM(J14:J18) -> 280000 | K19: =SUM(K14:K18) -> 3
A20: Подача в суд по ч\в. | B20: 0 | C20: 0 | D20: 0
A21: Сбор по исполнительным листам | B21: 6250000 | C21: 0 | D21: 6250000
A22: Сбор за экзамен | B22: 0 | C22: 0 | D22: 0
A23: Итого: | C23: =SUM(C15,C22) -> 560000
A25: Юрлидер
A26: Наименование | B26: Осталось собрать на 23.02 | C26: Факт с 23.02 по 01.03 | D26: План на 02.03
A27: Счета на юр услуги. | B27: 11 | C27: 20 | D27: 6
A28: Счета на вступления | B28: 4 | C28: 3 | D28: 3
A29: Сбор юр услуги | B29: 280000 | C29: 500000 | D29: 280000
A30: Вступления | B30: 5 | C30: 7 | D30: 3

Sheet 10 неделя
A2: 10 неделя с 02.03 по 08.03.2026
A3: Ростов | I3: Факт
A4: Наименование | B4: Осталось собрать на 02.03 | C4: Факт с 02.03 по 08.03 | D4: План на 09.03 | E4: План | H4: Счета Юр.услуги | I4: Счета Вступления | J4: Сбор Юр.услуги | K4: Кол-во вступлений
A5: Членские взносы | B5: =Таблица81419242934[[#This Row],[План на 02.03]] -> 9944710 | C5: 613505.38 | D5: =Таблица8141924293439[[#This Row],[Осталось собрать на 02.03]]-Таблица8141924293439[[#This Row],[Факт с 02.03 по 08.03]] -> 9331204.6 | G5: Наташа | H5: 7 | I5: 2 | J5: 90000 | K5: 0
A6: Долг действующие | B6: =Таблица81419242934[[#This Row],[План на 02.03]] -> 13586324 | C6: 332000 | D6: =Таблица8141924293439[[#This Row],[Осталось собрать на 02.03]]-Таблица8141924293439[[#This Row],[Факт с 02.03 по 08.03]] -> 13254324 | G6: Ира | H6: 3 | I6: 5 | J6: 110000 | K6: 5
A7: Долг исключенные | B7: =Таблица81419242934[[#This Row],[План на 02.03]] -> 9284746 | C7: 82298 | D7: =Таблица8141924293439[[#This Row],[Осталось собрать на 02.03]]-Таблица8141924293439[[#This Row],[Факт с 02.03 по 08.03]] -> 9202448 | G7: Таня | H7: 3 | I7: 2 | J7: 90000 | K7: 2
A8: переплата | B8: =Таблица81419242934[[#This Row],[План на 02.03]] -> 0 | C8: 332000 | G8: Роман | H8: 1 | I8: 0 | J8: 70000 | K8: 0
A9: Итого: | B9: =Таблица81419242934[[#This Row],[План на 02.03]] -> 32815780 | C9: =SUM(C5:C8) -> 1359803.4 | D9: =SUM(D5:D7) -> 31787977 | G9: Давид | H9: 3 | I9: 0 | J9: 85000 | K9: 0
G10: Итого: | H10: =SUM(H5:H9) -> 17 | I10: =SUM(I5:I9) -> 9 | J10: =SUM(J5:J9) -> 445000 | K10: =SUM(K5:K9) -> 7
A11: БГ
A12: Наименование | B12: Осталось собрать на 02.03 | C12: Факт с 02.03 по 08.03 | D12: План на 09.03 | I12: План
A13: Счета на чв | B13: 0 | C13: 0 | D13: 0 | H13: Счета Юр.услуги | I13: Счета Вступления | J13: Сбор Юр.услуги | K13: Кол-во вступлений
A14: Счета на юридические услуги. | B14: 4 | C14: 6 | D14: 4 | G14: Наташа | H14: 7 | I14: 1 | J14: 100000 | K14: 1
A15: Поступления по юр. Услугам. | B15: 200000 | C15: 315000 | D15: 200000 | G15: Ира | H15: 1 | I15: 1 | J15: 50000 | K15: 1
A16: Счета на прохождение экзамена | B16: 4 | C16: 3 | D16: 4 | G16: Таня | H16: 4 | I16: 1 | J16: 60000 | K16: 1
A17: Счета на вступления. | B17: 6 | C17: 9 | D17: 5 | G17: Роман | H17: 2 | I17: 0 | J17: 70000 | K17: 0
A18: Вступления. | B18: 6 | C18: 9 | D18: 5 | G18: Давид | H18: 2 | I18: 0 | J18: 100000 | K18: 0
A19: Получение исп. Листов | B19: 1 | C19: 1 | D19: 5 | G19: Итого: | H19: =SUM(H14:H18) -> 16 | I19: =SUM(I14:I18) -> 3 | J19: =SUM(J14:J18) -> 380000 | K19: =SUM(K14:K18) -> 3
A20: Подача в суд по ч\в. | B20: 0 | C20: 0 | D20: 0
A21: Сбор по исполнительным листам | B21: 6250000 | C21: 232500 | D21: 6020000
A22: Сбор за экзамен | B22: 0 | C22: 0 | D22: 0
A23: Итого: | C23: =C15+C21+C22 -> 547500
A25: Юрлидер
A26: Наименование | B26: Осталось собрать на 02.03 | C26: Факт с 02.03 по 08.03 | D26: План на 09.03
A27: Счета на юр услуги. | B27: 6 | C27: 17 | D27: 16
A28: Счета на вступления | B28: 3 | C28: 9 | D28: 3
A29: Сбор юр услуги | B29: 280000 | C29: 445000 | D29: 380000
A30: Вступления | B30: 3 | C30: 7 | D30: 3

Sheet 11 неделя
A2: 11 неделя с 09.03 по 15.03.2026
A3: Ростов | I3: Факт
A4: Наименование | B4: Осталось собрать на 09.03 | C4: Факт с 09.03 по 15.03 | D4: План на 16.03 | E4: План | H4: Счета Юр.услуги | I4: Счета Вступления | J4: Сбор Юр.услуги | K4: Кол-во вступлений
A5: Членские взносы | B5: =Таблица8141924293439[[#This Row],[План на 09.03]] -> 9331204.6 | C5: 982500 | D5: =Таблица814192429343944[[#This Row],[Осталось собрать на 09.03]]-Таблица814192429343944[[#This Row],[Факт с 09.03 по 15.03]] -> 8348704.6 | G5: Наташа | H5: 0 | I5: 0 | J5: 175000 | K5: 0
A6: Долг действующие | B6: =Таблица8141924293439[[#This Row],[План на 09.03]] -> 13254324 | C6: 346162.32 | D6: =Таблица814192429343944[[#This Row],[Осталось собрать на 09.03]]-Таблица814192429343944[[#This Row],[Факт с 09.03 по 15.03]] -> 12908162 | G6: Ира | H6: 1 | I6: 1 | J6: 80000 | K6: 0
A7: Долг исключенные | B7: =Таблица8141924293439[[#This Row],[План на 09.03]] -> 9202448 | C7: 129700 | D7: =Таблица814192429343944[[#This Row],[Осталось собрать на 09.03]]-Таблица814192429343944[[#This Row],[Факт с 09.03 по 15.03]] -> 9072748 | G7: Таня | H7: 1 | I7: 2 | J7: 5000 | K7: 1
A8: переплата | B8: =Таблица8141924293439[[#This Row],[План на 09.03]] -> 0 | C8: 40000 | G8: Роман | H8: 2 | I8: 0 | J8: 55000 | K8: 0
A9: Итого: | B9: =Таблица8141924293439[[#This Row],[План на 09.03]] -> 31787977 | C9: =SUM(C5:C8) -> 1498362.3 | D9: =SUM(D5:D7) -> 30329614 | G9: Давид | H9: 1 | I9: 2 | J9: 40000 | K9: 0
G10: Итого: | H10: =SUM(H5:H9) -> 5 | I10: =SUM(I5:I9) -> 5 | J10: =SUM(J5:J9) -> 355000 | K10: =SUM(K5:K9) -> 1
A11: БГ
A12: Наименование | B12: Осталось собрать на 09.03 | C12: Факт с 09.03 по 15.03 | D12: План на 16.03 | I12: План
A13: Счета на чв | B13: 0 | C13: 0 | D13: 0 | H13: Счета Юр.услуги | I13: Счета Вступления | J13: Сбор Юр.услуги | K13: Кол-во вступлений
A14: Счета на юридические услуги. | B14: 4 | C14: 5 | D14: 10 | G14: Наташа | H14: 10 | I14: 0 | J14: 100000 | K14: 0
A15: Поступления по юр. Услугам. | B15: 200000 | C15: 290000 | D15: 500000 | G15: Ира | H15: 10 | I15: 1 | J15: 50000 | K15: 1
A16: Счета на прохождение экзамена | B16: 4 | C16: 1 | D16: 3 | G16: Таня | H16: 6 | I16: 1 | J16: 70000 | K16: 1
A17: Счета на вступления. | B17: 5 | C17: 2 | D17: 5 | G17: Роман | H17: 2 | I17: 0 | J17: 80000 | K17: 0
A18: Вступления. | B18: 5 | C18: 2 | D18: 5 | G18: Давид | H18: 13 | I18: 0 | J18: 100000 | K18: 1
A19: Получение исп. Листов | B19: 5 | C19: 5 | D19: 0 | G19: Итого: | H19: =SUM(H14:H18) -> 41 | I19: =SUM(I14:I18) -> 2 | J19: =SUM(J14:J18) -> 400000 | K19: =SUM(K14:K18) -> 3
A20: Подача в суд по ч\в. | B20: 0 | C20: 0 | D20: 0
A21: Сбор по исполнительным листам | B21: 6020000 | C21: 471900 | D21: 6120000
A22: Сбор за экзамен | B22: 0 | C22: 0 | D22: 0
A23: Итого: | C23: =C15+C21+C22 -> 761900
A25: Юрлидер
A26: Наименование | B26: Осталось собрать на 09.03 | C26: Факт с 09.03 по 15.03 | D26: План на 16.03
A27: Счета на юр услуги. | B27: 16 | C27: 5 | D27: 41
A28: Счета на вступления | B28: 3 | C28: 5 | D28: 2
A29: Сбор юр услуги | B29: 380000 | C29: 355000 | D29: 400000
A30: Вступления | B30: 3 | C30: 1 | D30: 3

Sheet 12 неделя
A2: 12 неделя с 16.03 по 22.03.2026
A3: Ростов | I3: Факт
A4: Наименование | B4: Осталось собрать на 16.03 | C4: Факт с 16.03 по 22.03 | D4: План на 23.03 | E4: План | H4: Счета Юр.услуги | I4: Счета Вступления | J4: Сбор Юр.услуги | K4: Кол-во вступлений
A5: Членские взносы | B5: =Таблица814192429343944[[#This Row],[План на 16.03]] -> 8348704.6 | C5: 677000 | D5: =Таблица81419242934394456[[#This Row],[Осталось собрать на 16.03]]-Таблица81419242934394456[[#This Row],[Факт с 16.03 по 22.03]] -> 7671704.6 | G5: Наташа | H5: 13 | I5: 1 | J5: 340000 | K5: 0
A6: Долг действующие | B6: =Таблица814192429343944[[#This Row],[План на 16.03]] -> 12908162 | C6: 38000 | D6: =Таблица81419242934394456[[#This Row],[Осталось собрать на 16.03]]-Таблица81419242934394456[[#This Row],[Факт с 16.03 по 22.03]] -> 12870162 | G6: Ира | H6: 1 | I6: 1 | J6: 150000 | K6: 1
A7: Долг исключенные | B7: =Таблица814192429343944[[#This Row],[План на 16.03]] -> 9072748 | C7: 50000 | D7: =Таблица81419242934394456[[#This Row],[Осталось собрать на 16.03]]-Таблица81419242934394456[[#This Row],[Факт с 16.03 по 22.03]] -> 9022748 | G7: Таня | H7: 1 | I7: 2 | J7: 5000 | K7: 1
A8: переплата | B8: =Таблица814192429343944[[#This Row],[План на 16.03]] -> 0 | C8: 30000 | G8: Роман | H8: 3 | I8: 0 | J8: 80000 | K8: 0
A9: Итого: | B9: =Таблица814192429343944[[#This Row],[План на 16.03]] -> 30329614 | C9: =SUM(C5:C8) -> 795000 | D9: =SUM(D5:D7) -> 29564614 | G9: Давид | H9: 13 | I9: 1 | J9: 90000 | K9: 0
G10: Итого: | H10: =SUM(H5:H9) -> 31 | I10: =SUM(I5:I9) -> 5 | J10: =SUM(J5:J9) -> 665000 | K10: =SUM(K5:K9) -> 2
A11: БГ
A12: Наименование | B12: Осталось собрать на 16.03 | C12: Факт с 16.03 по 22.03 | D12: План на 23.03 | I12: План
A13: Счета на чв | B13: 0 | C13: 0 | D13: 0 | H13: Счета Юр.услуги | I13: Счета Вступления | J13: Сбор Юр.услуги | K13: Кол-во вступлений
A14: Счета на юридические услуги. | B14: 10 | C14: 4 | D14: 10 | G14: Наташа | H14: 5 | I14: 1 | J14: 150000 | K14: 1
A15: Поступления по юр. Услугам. | B15: 500000 | C15: 210000 | D15: 500000 | G15: Ира | H15: 2 | I15: 1 | J15: 50000 | K15: 1
A16: Счета на прохождение экзамена | B16: 3 | C16: 7 | D16: 3 | G16: Таня | H16: 6 | I16: 1 | J16: 70000 | K16: 1
A17: Счета на вступления. | B17: 5 | C17: 4 | D17: 5 | G17: Роман | H17: 2 | I17: 0 | J17: 100000 | K17: 0
A18: Вступления. | B18: 5 | C18: 4 | D18: 5 | G18: Давид | H18: 1 | I18: 1 | J18: 60000 | K18: 1
A19: Получение исп. Листов | B19: 0 | C19: 0 | D19: 5 | G19: Итого: | H19: =SUM(H14:H18) -> 16 | I19: =SUM(I14:I18) -> 4 | J19: =SUM(J14:J18) -> 430000 | K19: =SUM(K14:K18) -> 4
A20: Подача в суд по ч\в. | B20: 0 | C20: 0 | D20: 0
A21: Сбор по исполнительным листам | B21: 6120000 | C21: 42000 | D21: 6220000
A22: Сбор за экзамен | B22: 0 | C22: 0 | D22: 0
A23: Итого: | C23: =C15+C21+C22 -> 252000
A25: Юрлидер
A26: Наименование | B26: Осталось собрать на 16.03 | C26: Факт с 16.03 по 22.03 | D26: План на 23.03
A27: Счета на юр услуги. | B27: 41 | C27: 31 | D27: 16
A28: Счета на вступления | B28: 2 | C28: 5 | D28: 4
A29: Сбор юр услуги | B29: 400000 | C29: 665000 | D29: 430000
A30: Вступления | B30: 3 | C30: 2 | D30: 4

Sheet 13 неделя
A2: 13 неделя с 23.03 по 29.03.2026
A3: Ростов | I3: Факт
A4: Наименование | B4: Осталось собрать на 23.03 | C4: Факт с 23.01-30.03 | D4: осталось собрать на 30.03 | E4: План | H4: Счета Юр.услуги | I4: Счета Вступления | J4: Сбор Юр.услуги | K4: Кол-во вступлений
A5: Членские взносы | B5: =Таблица81419242934394456[[#This Row],[План на 23.03]] -> 7671704.6 | C5: 330500 | D5: =Таблица81465[[#This Row],[Осталось собрать на 23.03]]-Таблица81465[[#This Row],[Факт с 23.01-30.03]] -> 7341204.6 | G5: Наташа | H5: 1 | I5: 2 | J5: 170000 | K5: 1
A6: Долг действующие | B6: =Таблица81419242934394456[[#This Row],[План на 23.03]] -> 12870162 | C6: 83416 | D6: =Таблица81465[[#This Row],[Осталось собрать на 23.03]]-Таблица81465[[#This Row],[Факт с 23.01-30.03]] -> 12786746 | G6: Ира | H6: 1 | I6: 1 | J6: 140000 | K6: 2
A7: Долг исключенные | B7: =Таблица81419242934394456[[#This Row],[План на 23.03]] -> 9022748 | C7: 10000 | D7: =Таблица81465[[#This Row],[Осталось собрать на 23.03]]-Таблица81465[[#This Row],[Факт с 23.01-30.03]] -> 9012748 | G7: Таня | H7: 2 | I7: 1 | J7: 280000 | K7: 0
A8: переплата | B8: =Таблица81419242934394456[[#This Row],[План на 23.03]] -> 0 | C8: 90000 | G8: Роман | H8: 0 | I8: 0 | J8: 0 | K8: 0
A9: Итого: | B9: =Таблица81419242934394456[[#This Row],[План на 23.03]] -> 29564614 | C9: =SUM(C5:C8) -> 513916 | D9: =SUM(D5:D7) -> 29140698 | G9: Давид | H9: 1 | I9: 1 | J9: 110000 | K9: 0
G10: Итого: | H10: =SUM(H5:H9) -> 5 | I10: =SUBTOTAL(109,I5:I9) -> 5 | J10: =SUM(J5:J9) -> 700000 | K10: =SUM(K5:K9) -> 3
A11: БГ
A12: Наименование | B12: Осталось собрать на 23.03 | C12: Факт с 23.01-30.03 | D12: осталось собрать на 30.03 | I12: План
A13: Счета на чв | B13: 0 | C13: 0 | D13: 0 | H13: Счета Юр.услуги | I13: Счета Вступления | J13: Сбор Юр.услуги | K13: Кол-во вступлений
A14: Счета на юридические услуги. | B14: 10 | C14: 6 | D14: 5 | G14: Наташа | H14: 5 | I14: 1 | J14: 150000 | K14: 2
A15: Поступления по юр. Услугам. | B15: 500000 | C15: 295000 | D15: 250000 | G15: Ира | H15: 2 | I15: 1 | J15: 50000 | K15: 1
A16: Счета на прохождение экзамена | B16: 3 | C16: 1 | D16: 3 | G16: Таня | H16: 5 | I16: 1 | J16: 50000 | K16: 1
A17: Счета на вступления. | B17: 5 | C17: 5 | D17: 4 | G17: Роман | H17: 3 | I17: 0 | J17: 100000 | K17: 0
A18: Вступления. | B18: 5 | C18: 5 | D18: 4 | G18: Давид | H18: 1 | I18: 0 | J18: 90000 | K18: 0
A19: Получение исп. Листов | B19: 5 | C19: 0 | D19: 0 | G19: Итого: | H19: =SUM(H14:H18) -> 16 | I19: =SUM(I14:I18) -> 3 | J19: =SUM(J14:J18) -> 440000 | K19: =SUM(K14:K18) -> 4
A20: Подача в суд по ч\в. | B20: 0 | C20: 0 | D20: 0
A21: Сбор по исполнительным листам | B21: 6220000 | C21: 42000 | D21: 6120000
A22: Сбор за экзамен | B22: 0 | C22: 0 | D22: 0
A23: Итого: | C23: =SUM(C15,C21+C22) -> 337000
A25: Юрлидер
A26: Наименование | B26: Осталось собрать на 23.03 | C26: Факт с 23.01-30.03 | D26: осталось собрать на 30.03
A27: Счета на юр услуги. | B27: 16 | C27: 5 | D27: 16
A28: Счета на вступления | B28: 4 | C28: 5 | D28: 3
A29: Сбор юр услуги | B29: 43000 | C29: 700000 | D29: 440000
A30: Вступления | B30: 4 | C30: 3 | D30: 4

Sheet 14 неделя
A1: 14 неделя с 30.03 по 05.04.2026
A2: Ростов | H2: Факт
A3: Наименование | B3: Осталось собрать на 30.03 | C3: Факт с 30.03-05.04 | D3: осталось собрать на 06.04 | G3: Счета Юр.услуги | H3: Счета Вступления | I3: Сбор Юр.услуги | J3: Кол-во вступлений
A4: Членские взносы | B4: 21907700 | C4: 4727500 | D4: =Таблица8146571[[#This Row],[Осталось собрать на 30.03]]-Таблица8146571[[#This Row],[Факт с 30.03-05.04]] -> 17180200 | F4: Наташа | G4: 6 | H4: 2 | I4: 195000 | J4: 2
A5: Долг действующие | B5: 16361921 | C5: 53448.09 | D5: =Таблица8146571[[#This Row],[Осталось собрать на 30.03]]-Таблица8146571[[#This Row],[Факт с 30.03-05.04]] -> 16308473 | F5: Ира | G5: 1 | H5: 1 | I5: 50000 | J5: 2
A6: Долг исключенные | B6: 14307186 | C6: 33600 | D6: =Таблица8146571[[#This Row],[Осталось собрать на 30.03]]-Таблица8146571[[#This Row],[Факт с 30.03-05.04]] -> 14273586 | F6: Таня | G6: 1 | H6: 2 | I6: 134000 | J6: 0
A7: переплата | C7: 568000 | F7: Роман | G7: 2 | H7: 0 | I7: 0 | J7: 0
A8: Переплаты исключеных | B8: 1573000.2 | F8: Давид | G8: 1 | H8: 1 | I8: 175000 | J8: 1
A9: Итого: | B9: =SUM(B4:B6) -> 52576807 | C9: =SUM(C4:C7) -> 5382548.1 | D9: =SUM(D4:D6) -> 47762259 | F9: Итого: | G9: =SUM(G4:G8) -> 11 | H9: =SUM(H4:H8) -> 6 | I9: =SUM(I4:I8) -> 554000 | J9: =SUM(J4:J8) -> 5
A11: БГ | H11: План
A12: Наименование | B12: Осталось собрать на 30.03 | C12: Факт с 30.03-05.04 | D12: План на 06.04 | G12: Счета Юр.услуги | H12: Счета Вступления | I12: Сбор Юр.услуги | J12: Кол-во вступлений
A13: Счета на чв | B13: ='13 неделя'!D13 -> 0 | C13: 0 | D13: 0 | F13: Наташа | G13: 8 | H13: 1 | I13: 100000 | J13: 1
A14: Счета на юридические услуги. | B14: ='13 неделя'!D14 -> 5 | C14: 5 | D14: 4 | F14: Ира | G14: 2 | H14: 1 | I14: 50000 | J14: 1
A15: Поступления по юр. Услугам. | B15: ='13 неделя'!D15 -> 250000 | C15: 235000 | D15: 200000 | F15: Таня | G15: 5 | H15: 1 | I15: 50000 | J15: 1
A16: Счета на прохождение экзамена | B16: ='13 неделя'!D16 -> 3 | C16: 3 | D16: 3 | F16: Роман | G16: 3 | H16: 0 | I16: 100000 | J16: 0
A17: Счета на вступления. | B17: ='13 неделя'!D17 -> 4 | C17: 3 | D17: 3 | F17: Давид | G17: 3 | H17: 0 | I17: 70000 | J17: 0
A18: Вступления. | B18: ='13 неделя'!D18 -> 4 | C18: 5 | D18: 4 | F18: Итого: | G18: =SUM(G13:G17) -> 21 | H18: =SUM(H13:H17) -> 3 | I18: =SUM(I13:I17) -> 370000 | J18: =SUM(J13:J17) -> 3
A19: Получение исп. Листов | B19: ='13 неделя'!D19 -> 0 | C19: 5 | D19: 12
A20: Подача в суд по ч\в. | B20: ='13 неделя'!D20 -> 0 | C20: 0 | D20: 0
A21: Сбор по исполнительным листам | B21: ='13 неделя'!D21 -> 6120000 | C21: 24500 | D21: 6320000
A22: Сбор за экзамен | B22: ='13 неделя'!D22 -> 0
A23: Итого: | B23: ='13 неделя'!D23 -> 0 | C23: =SUM(C15,C21+C22) -> 259500
A25: Юрлидер
A26: Наименование | B26: Осталось собрать на 30.03 | C26: Факт с 30.03-05.04 | D26: План на 06.04
A27: Счета на юр услуги. | B27: ='13 неделя'!D27 -> 16 | C27: 11 | D27: 21
A28: Счета на вступления | B28: ='13 неделя'!D28 -> 3 | C28: 6 | D28: 3
A29: Сбор юр услуги | B29: ='13 неделя'!D29 -> 440000 | C29: 554000 | D29: 370000
A30: Вступления | B30: ='13 неделя'!D30 -> 4 | C30: 5 | D30: 3

Sheet 15 неделя
A1: 15 неделя с 06.04 по 12.04.2026
A2: Ростов | I2: Факт
A3: Ростов | B3: Осталось собрать на 06.04 | C3: Факт с 06.04-12.04 | D3: осталось собрать на 13.04 | E3: План | H3: Счета Юр.услуги | I3: Счета Вступления | J3: Сбор Юр.услуги | K3: Кол-во вступлений
A4: Членские взносы | B4: =Таблица8146571[[#This Row],[осталось собрать на 06.04]] -> 17180200 | C4: 2388100 | D4: =Таблица814657149[[#This Row],[Осталось собрать на 06.04]]-Таблица814657149[[#This Row],[Факт с 06.04-12.04]] -> 14792100 | G4: Наташа | H4: 2 | I4: 6 | J4: 280000 | K4: 3
A5: Долг действующие | B5: =Таблица8146571[[#This Row],[осталось собрать на 06.04]] -> 16308473 | C5: 99200 | D5: =Таблица814657149[[#This Row],[Осталось собрать на 06.04]]-Таблица814657149[[#This Row],[Факт с 06.04-12.04]] -> 16209273 | G5: Ира | H5: 1 | I5: 1 | J5: 0 | K5: 0
A6: Долг исключенные | B6: =Таблица8146571[[#This Row],[осталось собрать на 06.04]] -> 14273586 | C6: 52237.03 | D6: =Таблица814657149[[#This Row],[Осталось собрать на 06.04]]-Таблица814657149[[#This Row],[Факт с 06.04-12.04]] -> 14221349 | G6: Таня | H6: 1 | I6: 1 | J6: 60000 | K6: 0
A7: переплата | C7: 312250 | G7: Роман | H7: 0 | I7: 0 | J7: 0 | K7: 0
A8: Переплаты исключеных | B8: 1573000.2 | G8: Давид | H8: 1 | I8: 2 | J8: 0 | K8: 0
A9: Итого: | B9: =Таблица8146571[[#This Row],[осталось собрать на 06.04]] -> 47762259 | C9: =SUM(C4:C7) -> 2851787 | D9: =Таблица814657149[[#This Row],[Осталось собрать на 06.04]]-Таблица814657149[[#This Row],[Факт с 06.04-12.04]] -> 44910472 | G9: Итого: | H9: =SUM(H4:H8) -> 5 | I9: =SUM(I4:I8) -> 10 | J9: =SUM(J4:J8) -> 340000 | K9: =SUM(K4:K8) -> 3
A10: БГ
A11: Наименование | B11: План на 06.04 | C11: Факт с 06.04-12.04 | D11: План на 13.04 | I11: План
A12: Счета на чв | B12: ='14 неделя'!D13 -> 0 | C12: 0 | D12: 0 | H12: Счета Юр.услуги | I12: Счета Вступления | J12: Сбор Юр.услуги | K12: Кол-во вступлений
A13: Счета на юридические услуги. | B13: ='14 неделя'!D14 -> 4 | C13: 0 | D13: 3 | G13: Наташа | H13: 10 | I13: 2 | J13: 150000 | K13: 1
A14: Поступления по юр. Услугам. | B14: ='14 неделя'!D15 -> 200000 | C14: 0 | D14: 150000 | G14: Ира | H14: 11 | I14: 1 | J14: 50000 | K14: 1
A15: Счета на прохождение экзамена | B15: ='14 неделя'!D16 -> 3 | C15: 3 | D15: 3 | G15: Таня | H15: 5 | I15: 1 | J15: 150000 | K15: 1
A16: Счета на вступления. | B16: ='14 неделя'!D17 -> 3 | C16: 2 | D16: 3 | G16: Роман | H16: 3 | I16: 0 | J16: 100000 | K16: 0
A17: Вступления. | B17: ='14 неделя'!D18 -> 4 | C17: 2 | D17: 3 | G17: Давид | H17: 7 | I17: 0 | J17: 80000 | K17: 2
A18: Получение исп. Листов | B18: ='14 неделя'!D19 -> 12 | C18: 12 | D18: 4 | G18: Итого: | H18: =SUM(H13:H17) -> 36 | I18: =SUM(I13:I17) -> 4 | J18: =SUM(J13:J17) -> 530000 | K18: =SUM(K13:K17) -> 5
A19: Подача в суд по ч\в. | B19: ='14 неделя'!D20 -> 0 | C19: 0 | D19: 0
A20: Сбор по исполнительным листам | B20: ='14 неделя'!D21 -> 6320000 | C20: 60000 | D20: 6260000
A21: Сбор за экзамен
A22: Итого: | C22: =C14+C20+C21 -> 60000
A24: Юрлидер
A25: Наименование | B25: План на 06.04 | C25: Факт с 06.04-12.04 | D25: План на 13.04
A26: Счета на юр услуги. | B26: ='14 неделя'!D27 -> 21 | C26: 5 | D26: 36
A27: Счета на вступления | B27: ='14 неделя'!D28 -> 3 | C27: 10 | D27: 4
A28: Сбор юр услуги | B28: ='14 неделя'!D29 -> 370000 | C28: 340000 | D28: 530000
A29: Вступления | B29: ='14 неделя'!D30 -> 3 | C29: 3 | D29: 5

Sheet 16 неделя
A1: 16 неделя с 13.04 по 19.04.2026
A2: Ростов | I2: Факт
A3: Ростов | B3: Осталось собрать на 13.04 | C3: Факт с 13.04-19.04 | D3: осталось собрать на 20.04 | E3: План | H3: Счета Юр.услуги | I3: Счета Вступления | J3: Сбор Юр.услуги | K3: Кол-во вступлений
A4: Членские взносы | B4: =Таблица814657149[[#This Row],[осталось собрать на 13.04]] -> 14792100 | C4: 1818000 | D4: =Таблица81465714917[[#This Row],[Осталось собрать на 13.04]]-Таблица81465714917[[#This Row],[Факт с 13.04-19.04]] -> 12974100 | G4: Наташа | H4: 3 | I4: 0 | J4: 105000 | K4: 0
A5: Долг действующие | B5: =Таблица814657149[[#This Row],[осталось собрать на 13.04]] -> 16209273 | C5: 120000 | D5: =Таблица81465714917[[#This Row],[Осталось собрать на 13.04]]-Таблица81465714917[[#This Row],[Факт с 13.04-19.04]] -> 16089273 | G5: Ира | H5: 1 | I5: 2 | J5: 355000 | K5: 1
A6: Долг исключенные | B6: =Таблица814657149[[#This Row],[осталось собрать на 13.04]] -> 14221349 | C6: 6152.31 | D6: =Таблица81465714917[[#This Row],[Осталось собрать на 13.04]]-Таблица81465714917[[#This Row],[Факт с 13.04-19.04]] -> 14215196 | G6: Таня | H6: 3 | I6: 0 | J6: 155000 | K6: 0
A7: переплата | C7: 2493500 | G7: Роман | H7: 3 | I7: 0 | J7: 110000 | K7: 0
A8: Переплаты исключеных | B8: 1573000.2 | G8: Давид | H8: 1 | I8: 0 | J8: 0 | K8: 0
A9: Итого: | B9: =Таблица814657149[[#This Row],[осталось собрать на 13.04]] -> 44910472 | C9: =SUM(C4:C7) -> 4437652.3 | D9: =Таблица81465714917[[#This Row],[Осталось собрать на 13.04]]-Таблица81465714917[[#This Row],[Факт с 13.04-19.04]] -> 40472819 | G9: Итого: | H9: =SUM(H4:H8) -> 11 | I9: =SUM(I4:I8) -> 2 | J9: =SUM(J4:J8) -> 725000 | K9: =SUM(K4:K8) -> 1
A10: БГ
A11: Наименование | B11: План на 13.04 | C11: Факт с 13.04-19.04 | D11: План на 20.04 | I11: План
A12: Счета на чв | B12: =Таблица915667250[[#This Row],[План на 13.04]] -> 0 | C12: 0 | D12: 0 | H12: Счета Юр.услуги | I12: Счета Вступления | J12: Сбор Юр.услуги | K12: Кол-во вступлений
A13: Счета на юридические услуги. | B13: =Таблица915667250[[#This Row],[План на 13.04]] -> 3 | C13: 4 | D13: 7 | G13: Наташа | H13: 5 | I13: 0 | J13: 100000 | K13: 0
A14: Поступления по юр. Услугам. | B14: =Таблица915667250[[#This Row],[План на 13.04]] -> 150000 | C14: 220000 | D14: 350000 | G14: Ира | H14: 1 | I14: 1 | J14: 50000 | K14: 1
A15: Счета на прохождение экзамена | B15: =Таблица915667250[[#This Row],[План на 13.04]] -> 3 | C15: 2 | D15: 4 | G15: Таня | H15: 5 | I15: 0 | J15: 100000 | K15: 0
A16: Счета на вступления. | B16: =Таблица915667250[[#This Row],[План на 13.04]] -> 3 | C16: 8 | D16: 4 | G16: Роман | H16: 3 | I16: 0 | J16: 100000 | K16: 0
A17: Вступления. | B17: =Таблица915667250[[#This Row],[План на 13.04]] -> 3 | C17: 8 | D17: 4 | G17: Давид | H17: 13 | I17: 1 | J17: 120000 | K17: 1
A18: Получение исп. Листов | B18: =Таблица915667250[[#This Row],[План на 13.04]] -> 4 | C18: 4 | D18: 1 | G18: Итого: | H18: =SUM(H13:H17) -> 27 | I18: =SUM(I13:I17) -> 2 | J18: =SUM(J13:J17) -> 470000 | K18: =SUM(K13:K17) -> 2
A19: Подача в суд по ч\в. | B19: =Таблица915667250[[#This Row],[План на 13.04]] -> 0 | C19: 0 | D19: 30
A20: Сбор по исполнительным листам | B20: =Таблица915667250[[#This Row],[План на 13.04]] -> 6260000 | C20: 13370 | D20: 6380000
A21: Сбор за экзамен
A22: Итого: | C22: =C14+C20+C21 -> 233370
A24: Юрлидер
A25: Наименование | B25: План на 13.04 | C25: Факт с 13.04-19.04 | D25: План на 20.01
A26: Счета на юр услуги. | B26: =Таблица50[[#This Row],[План на 13.04]] -> 36 | C26: 11 | D26: 27
A27: Счета на вступления | B27: =Таблица50[[#This Row],[План на 13.04]] -> 4 | C27: 2 | D27: 2
A28: Сбор юр услуги | B28: =Таблица50[[#This Row],[План на 13.04]] -> 530000 | C28: 725000 | D28: 470000
A29: Вступления | B29: =Таблица50[[#This Row],[План на 13.04]] -> 5 | C29: 1 | D29: 2

Sheet 17 неделя
A1: 17 неделя с 20.04 по 26.04.2026
A2: Ростов
A3: Ростов | B3: Осталось собрать на 20.04 | C3: Факт с 20.04-26.04 | D3: осталось собрать на 27.04 | E3: План | J3: Факт
A4: Начислено за квартал | B4: 24924000 | I4: Счета Юр.услуги | J4: Счета Вступления | K4: Сбор Юр.услуги | L4: Кол-во вступлений
A5: Переплата за квартал | B5: 3016300 | H5: Наташа | I5: 2 | J5: 0 | K5: 190000 | L5: 0
A6: План сбора за квартал | B6: 12974100 | C6: 625000 | D6: 12604100 | H6: Ира | I6: 1 | J6: 1 | K6: 215000 | L6: 1
A7: Долг действующие | B7: 16089273 | C7: 110000 | D7: 15979273 | H7: Таня | I7: 5 | J7: 1 | K7: 60000 | L7: 0
A8: Долг исключенные | B8: 14215196 | C8: 40000 | D8: 14175196 | H8: Роман | I8: 7 | J8: 0 | K8: 150000 | L8: 0
A9: Сбор ЧВ по вступившим в этом квартале | B9: 730000 | C9: 190000 | D9: =Таблица8146571491760[[#This Row],[Осталось собрать на 20.04]]+Таблица8146571491760[[#This Row],[Факт с 20.04-26.04]] -> 920000 | H9: Давид | I9: 13 | J9: 1 | K9: 370000 | L9: 0
A10: Переплата | C10: 100000 | H10: Итого: | I10: =SUM(I5:I9) -> 28 | J10: =SUM(J5:J9) -> 3 | K10: =SUM(K5:K9) -> 985000 | L10: =SUM(L5:L9) -> 1
A11: Сумма ЧВ у пристовов
A12: Сумма ЧВ в суде
A13: Поступление от судебной деятельности | J13: План
A14: Итого: | B14: =B6+B7+B8 -> 43278569 | C14: =SUM(C6:C10) -> 1065000 | D14: =SUM(D6:D8) -> 42758569 | I14: Счета Юр.услуги | J14: Счета Вступления | K14: Сбор Юр.услуги | L14: Кол-во вступлений
H15: Наташа | I15: 3 | J15: 0 | K15: 150000 | L15: 0
H16: Ира | I16: 1 | J16: 1 | K16: 50000 | L16: 1
A17: БГ | H17: Таня | I17: 4 | J17: 0 | K17: 100000 | L17: 1
A18: Наименование | B18: План на 20.04 | C18: Факт с 20.04-26.04 | D18: План на 27.04 | H18: Роман | I18: 2 | J18: 0 | K18: 100000 | L18: 0
A19: Счета на чв | B19: 0 | C19: 0 | D19: 0 | H19: Давид | I19: 1 | J19: 0 | K19: 100000 | L19: 1
A20: Счета на юридические услуги. | B20: 7 | C20: 14 | D20: 5 | H20: Итого: | I20: =SUM(I15:I19) -> 11 | J20: =SUM(J15:J19) -> 1 | K20: =SUM(K15:K19) -> 500000 | L20: =SUM(L15:L19) -> 3
A21: Поступления по юр. Услугам. | B21: 350000 | C21: 760000 | D21: 250000
A22: Счета на прохождение экзамена | B22: 4 | C22: 1 | D22: 2
A23: Счета на вступления. | B23: 4 | C23: 6 | D23: 3
A24: Вступления. | B24: 4 | C24: 6 | D24: 3
A25: Получение исп. Листов | B25: 1 | C25: 1 | D25: 0
A26: Подача в суд по ч\в. | B26: 30 | C26: 30 | D26: 46
A27: Сбор по исполнительным листам | B27: 6380000 | C27: 0 | D27: 6680000
A28: Сбор за экзамен | B28: 0 | C28: 0
A29: Итого: | C29: =C213 -> 0
A31: Юрлидер
A32: Наименование | B32: План на 20.04 | C32: Факт с 20.04-26.04 | D32: План на 27.01
A33: Счета на юр услуги. | B33: 27 | C33: 28 | D33: 11
A34: Счета на вступления | B34: 2 | C34: 3 | D34: 1
A35: Сбор юр услуги | B35: 470000 | C35: 985000 | D35: 500000
A36: Вступления | B36: 2 | C36: 1 | D36: 3

Sheet 18 неделя
A1: 18 неделя с 27.04 по 03.05.2026
A2: Ростов | I2: Факт
A3: Ростов | B3: Осталось собрать на 27.04 | C3: Факт с 27.04-03.05 | D3: осталось собрать на 04.05 | E3: План | H3: Счета Юр.услуги | I3: Счета Вступления | J3: Сбор Юр.услуги | K3: Кол-во вступлений
A4: Начислено за квартал | B4: 24924000 | G4: Наташа | H4: 2 | I4: 0 | J4: 110000 | K4: 0
A5: Переплата за квартал | B5: 3016300 | G5: Ира | H5: 1 | I5: 1 | J5: 30000 | K5: 1
A6: План сбора за квартал | B6: 12604100 | C6: 417000 | D6: =Таблица814657149176070[[#This Row],[Осталось собрать на 27.04]]-Таблица814657149176070[[#This Row],[Факт с 27.04-03.05]] -> 12187100 | G6: Таня | H6: 2 | I6: 1 | J6: 35000 | K6: 1
A7: Долг действующие | B7: 15979273 | C7: 40000 | D7: =Таблица814657149176070[[#This Row],[Осталось собрать на 27.04]]-Таблица814657149176070[[#This Row],[Факт с 27.04-03.05]] -> 15939273 | G7: Роман | H7: 2 | I7: 0 | J7: 140000 | K7: 0
A8: Долг исключенные | B8: 14175196 | C8: 20000 | D8: =Таблица814657149176070[[#This Row],[Осталось собрать на 27.04]]-Таблица814657149176070[[#This Row],[Факт с 27.04-03.05]] -> 14155196 | G8: Давид | H8: 1 | I8: 1 | J8: 0 | K8: 1
A9: Сбор ЧВ по вступившим в этом квартале | B9: =Таблица8146571491760[[#This Row],[осталось собрать на 27.04]] -> 920000 | C9: 30000 | D9: =Таблица814657149176070[[#This Row],[Осталось собрать на 27.04]]+Таблица814657149176070[[#This Row],[Факт с 27.04-03.05]] -> 950000 | G9: Итого: | H9: =SUM(H4:H8) -> 8 | I9: =SUM(I4:I8) -> 3 | J9: =SUM(J4:J8) -> 315000 | K9: =SUM(K4:K8) -> 3
A10: Переплата | C10: 110000
A11: Сумма ЧВ у пристовов | C11: =C279+SUM(C27,C29) -> 7150000
A12: Сумма ЧВ в суде | C12: =SUM(C28,C30) -> 20302000 | I12: План
A13: Поступление от судебной деятельности | C13: =SUM(C31,C32) -> 40000 | H13: Счета Юр.услуги | I13: Счета Вступления | J13: Сбор Юр.услуги | K13: Кол-во вступлений
A14: Итого: | B14: =B6+B7+B8 -> 42758569 | C14: =SUM(C6:C10) -> 617000 | D14: =D6+D7+D8 -> 42281569 | G14: Наташа | H14: 2 | I14: 0 | J14: 100000 | K14: 0
G15: Ира | H15: 1 | I15: 1 | J15: 50000 | K15: 1
G16: Таня | H16: 2 | I16: 0 | J16: 30000 | K16: 1
A17: БГ | G17: Роман | H17: 1 | I17: 0 | J17: 70000 | K17: 0
A18: Наименование | B18: План на 27.04 | C18: Факт с 27.04-03.05 | D18: План на 04.05 | G18: Давид | H18: 2 | I18: 0 | J18: 70000 | K18: 1
A19: Счета на чв | G19: Итого: | H19: =SUM(H14:H18) -> 8 | I19: =SUM(I14:I18) -> 1 | J19: =SUM(J14:J18) -> 320000 | K19: =SUM(K14:K18) -> 3
A20: Счета на юридические услуги. | B20: 5 | C20: 8 | D20: 3
A21: Поступления по юр. Услугам. | B21: 250000 | C21: 495000 | D21: 150000
A22: Счета на прохождение экзамена | B22: 2 | C22: 1 | D22: 2
A23: Счета на вступления. | B23: 3 | C23: 4 | D23: 3
A24: Вступления. | B24: 3 | C24: 1 | D24: 3
A25: Сбор за экзамен | C25: 42000 | D25: 84000
A26: Итого: | C26: =C21+C25 -> 537000
A27: Сумма ЧВ у приставов действ | C27: 2700000
A28: Сумма ЧВ в суде действ | C28: 8275000
A29: Сумма ЧВ у приставов искл | C29: 4450000
A30: Сумма ЧВ в суде искл | C30: 12027000
A31: Поступления по СД искл | C31: 0
A32: Поступление по СД действ | C32: 40000
A33: ИТОГО в суде | C33: 20302000
A34: Юрлидер
A35: Наименование | B35: План на 27.04 | C35: Факт с 27.04-03.05 | D35: План на 04.05
A36: Счета на юр услуги. | B36: 11 | C36: 8 | D36: 8
A37: Счета на вступления | B37: 1 | C37: 3 | D37: 1
A38: Сбор юр услуги | B38: 500000 | C38: 315000 | D38: 320000
A39: Вступления | B39: 3 | C39: 3 | D39: 3

Sheet 19 неделя
A1: 19 неделя с 04.05.2026 по 10.05.2026
A2: Ростов | I2: Факт
A3: Ростов | B3: Осталось собрать на 04.05 | C3: Факт с 04.05-10.05 | D3: осталось собрать на 11.05-17.05 | E3: План | H3: Счета Юр.услуги | I3: Счета Вступления | J3: Сбор Юр.услуги | K3: Кол-во вступлений
A4: Начислено за квартал | B4: =Таблица814657149176070[[#This Row],[Осталось собрать на 27.04]] -> 24924000 | G4: Наташа | H4: 4 | I4: 1 | J4: 180000 | K4: 0
A5: Переплата за квартал | B5: =Таблица814657149176070[[#This Row],[Осталось собрать на 27.04]] -> 3016300 | G5: Ира | H5: 1 | I5: 1 | J5: 140000 | K5: 1
A6: План сбора за квартал | B6: =Таблица814657149176070[[#This Row],[осталось собрать на 04.05]] -> 12187100 | C6: 307000 | D6: =Таблица81465714917607082[[#This Row],[Осталось собрать на 04.05]]-Таблица81465714917607082[[#This Row],[Факт с 04.05-10.05]] -> 11880100 | G6: Таня | H6: 1 | I6: 1 | J6: 5000 | K6: 0
A7: Долг действующие | B7: =Таблица814657149176070[[#This Row],[осталось собрать на 04.05]] -> 15939273 | C7: 36500 | D7: =Таблица81465714917607082[[#This Row],[Осталось собрать на 04.05]]-Таблица81465714917607082[[#This Row],[Факт с 04.05-10.05]] -> 15902773 | G7: Роман | H7: 0 | I7: 0 | J7: 35000 | K7: 0
A8: Долг исключенные | B8: =Таблица814657149176070[[#This Row],[осталось собрать на 04.05]] -> 14155196 | C8: 278801.29 | D8: =Таблица81465714917607082[[#This Row],[Осталось собрать на 04.05]]-Таблица81465714917607082[[#This Row],[Факт с 04.05-10.05]] -> 13876395 | G8: Давид | H8: 2 | I8: 0 | J8: 0 | K8: 0
A9: Сбор ЧВ по вступившим в этом квартале | B9: =Таблица814657149176070[[#This Row],[осталось собрать на 04.05]] -> 950000 | C9: 120000 | D9: =SUM(Таблица81465714917607082[[#This Row],[Осталось собрать на 04.05]],Таблица81465714917607082[[#This Row],[Факт с 04.05-10.05]]) -> 1070000 | G9: Итого: | H9: =SUM(H4:H8) -> 8 | I9: =SUM(I4:I8) -> 3 | J9: =SUM(J4:J8) -> 360000 | K9: =SUM(K4:K8) -> 1
A10: Переплата | C10: 100000
A11: Сумма ЧВ у пристовов | C11: =SUM(B28,B30) -> 6901300
A12: Сумма ЧВ в суде | C12: =SUM(B29,B31) -> 20302000 | I12: План
A13: Поступление от судебной деятельности | C13: =SUM(B32,B33) -> 248700 | H13: Счета Юр.услуги | I13: Счета Вступления | J13: Сбор Юр.услуги | K13: Кол-во вступлений
A14: Итого: | B14: =Таблица814657149176070[[#This Row],[осталось собрать на 04.05]] -> 42281569 | C14: =SUM(C6:C10) -> 842301.29 | D14: =SUM(D6:D8) -> 41659268 | G14: Наташа | H14: 3 | I14: 0 | J14: 100000 | K14: 0
G15: Ира | H15: 10 | I15: 1 | J15: 50000 | K15: 1
A16: БГ | G16: Таня | H16: 3 | I16: 1 | J16: 100000 | K16: 1
A17: Наименование | B17: План на 04.05 | C17: Факт с 04.05-10.05 | D17: План на 11.05-17.05 | G17: Роман | H17: 1 | I17: 0 | J17: 70000 | K17: 0
A18: Счета на юридические услуги. | B18: 3 | C18: 5 | D18: 3 | G18: Давид | H18: 1 | I18: 0 | J18: 50000 | K18: 1
A19: Поступления по юр. Услугам. | B19: 150000 | C19: 255000 | D19: 150000 | G19: Итого: | H19: =SUM(H14:H18) -> 18 | I19: =SUM(I14:I18) -> 2 | J19: =SUM(J14:J18) -> 370000 | K19: =SUM(K14:K18) -> 3
A20: Счета на прохождение экзамена | B20: 2 | C20: 2 | D20: 3
A21: Счета на вступления. | B21: 3 | C21: 5 | D21: 3
A22: Вступления. | B22: 3 | C22: 2 | D22: 3
A23: Сбор за экзамен | B23: 84000 | C23: 84000 | D23: 126000
A24: Итого: | C24: =C19+C23 -> 339000
A26: Олег
A27: Наименование | B27: Факт с 04.05-10.05
A28: Сумма ЧВ у приставов действ | B28: 2700000
A29: Сумма ЧВ в суде действ | B29: 8275000
A30: Сумма ЧВ у приставов искл | B30: 4201300
A31: Сумма ЧВ в суде искл | B31: 12027000
A32: Поступления по СД искл | B32: 248700
A33: Поступление по СД действ | B33: 0
A34: ИТОГО в суде | B34: 19873300
A36: Юрлидер
A37: Наименование | B37: План на 04.05 | C37: Факт с 04.05-10.05 | D37: План на 11.05-17.05
A38: Счета на юр услуги. | B38: ='18 неделя'!D36 -> 8 | C38: 8 | D38: 18
A39: Счета на вступления | B39: ='18 неделя'!D37 -> 1 | C39: 3 | D39: 2
A40: Сбор юр услуги | B40: ='18 неделя'!D38 -> 320000 | C40: 360000 | D40: 370000
A41: Вступления | B41: ='18 неделя'!D39 -> 3 | C41: 1 | D41: 3
A43: Барановская
...

Sheet 20 неделя
A1: 20 неделя с 11.05.2026 по 17.05.2026
A2: Ростов | I2: Факт
A3: Ростов | B3: Осталось собрать на 11.05 | C3: Факт с 11.05-17.05 | D3: осталось собрать на 18.05-24.05 | E3: План | H3: Счета Юр.услуги | I3: Счета Вступления | J3: Сбор Юр.услуги | K3: Кол-во вступлений
A4: Начислено за квартал | B4: =Таблица814657149176070[[#This Row],[Осталось собрать на 27.04]] -> 24924000 | G4: Наташа | H4: 2 | I4: 2 | J4: 5000 | K4: 1
A5: Переплата за квартал | B5: =Таблица814657149176070[[#This Row],[Осталось собрать на 27.04]] -> 3016300 | G5: Ира | H5: 20 | I5: 1 | J5: 65000 | K5: 0
A6: План сбора за квартал | B6: =Таблица81465714917607082[[#This Row],[осталось собрать на 11.05-17.05]] -> 11880100 | C6: 884000 | D6: =Таблица8146571491760708283[[#This Row],[Осталось собрать на 11.05]]-Таблица8146571491760708283[[#This Row],[Факт с 11.05-17.05]] -> 10996100 | G6: Таня | H6: 2 | I6: 2 | J6: 140000 | K6: 1
A7: Долг действующие | B7: =Таблица81465714917607082[[#This Row],[осталось собрать на 11.05-17.05]] -> 15902773 | C7: 45500 | D7: =Таблица8146571491760708283[[#This Row],[Осталось собрать на 11.05]]-Таблица8146571491760708283[[#This Row],[Факт с 11.05-17.05]] -> 15857273 | G7: Роман | H7: 1 | I7: 0 | J7: 70000 | K7: 0
A8: Долг исключенные | B8: =Таблица81465714917607082[[#This Row],[осталось собрать на 11.05-17.05]] -> 13876395 | C8: 145600 | D8: =Таблица8146571491760708283[[#This Row],[Осталось собрать на 11.05]]-Таблица8146571491760708283[[#This Row],[Факт с 11.05-17.05]] -> 13730795 | G8: Давид | H8: 0 | I8: 1 | J8: 40000 | K8: 1
A9: Сбор ЧВ по вступившим в этом квартале | B9: =Таблица81465714917607082[[#This Row],[осталось собрать на 11.05-17.05]] -> 1070000 | C9: 150000 | D9: =Таблица8146571491760708283[[#This Row],[Осталось собрать на 11.05]]+Таблица8146571491760708283[[#This Row],[Факт с 11.05-17.05]] -> 1220000 | G9: Итого: | H9: =SUM(H4:H8) -> 25 | I9: =SUM(I4:I8) -> 6 | J9: =SUM(J4:J8) -> 320000 | K9: =SUM(K4:K8) -> 3
A10: Переплата | C10: 316960.01
A11: Сумма ЧВ у пристовов | C11: =B28+B30 -> 6699300
A12: Сумма ЧВ в суде | C12: =B29+B31 -> 20302000 | I12: План
A13: Поступление от судебной деятельности | C13: =B32+B33 -> 202000 | H13: Счета Юр.услуги | I13: Счета Вступления | J13: Сбор Юр.услуги | K13: Кол-во вступлений
A14: Итого: | B14: =Таблица81465714917607082[[#This Row],[осталось собрать на 11.05-17.05]] -> 41659268 | C14: =SUM(C6:C10) -> 1542060 | D14: =SUM(D6:D8) -> 40584168 | G14: Наташа | H14: 10 | I14: 0 | J14: 100000 | K14: 1
G15: Ира | H15: 1 | I15: 1 | J15: 50000 | K15: 1
A16: БГ | G16: Таня | H16: 5 | I16: 1 | J16: 30000 | K16: 1
A17: Наименование | B17: План на 11.05 | C17: Факт с 11.05-17.05 | D17: План на 18.05-24.05 | G17: Роман | H17: 2 | I17: 0 | J17: 70000 | K17: 0
A18: Счета на юридические услуги. | B18: {='19 неделя'!D18:D23} -> 3 | C18: 3 | D18: 3 | G18: Давид | H18: 10 | I18: 0 | J18: 150000 | K18: 0
A19: Поступления по юр. Услугам. | B19: 150000 | C19: 220000 | D19: 150000 | G19: Итого: | H19: =SUM(H14:H18) -> 28 | I19: =SUM(I14:I18) -> 2 | J19: =SUM(J14:J18) -> 400000 | K19: =SUM(K14:K18) -> 3
A20: Счета на прохождение экзамена | B20: 3 | C20: 0 | D20: 2
A21: Счета на вступления. | B21: 3 | C21: 5 | D21: 3
A22: Вступления. | B22: 3 | C22: 3 | D22: 3
A23: Сбор за экзамен | B23: 126000 | C23: 0 | D23: 84000
A24: Итого: | C24: =C19+C23 -> 220000
A26: Олег
A27: Наименование | B27: Факт с 11.05-17.05
A28: Сумма ЧВ у приставов действ | B28: 2700000
A29: Сумма ЧВ в суде действ | B29: 8275000
A30: Сумма ЧВ у приставов искл | B30: 3999300
A31: Сумма ЧВ в суде искл | B31: 12027000
A32: Поступления по СД искл | B32: 202000
A33: Поступление по СД действ | B33: 0
A34: ИТОГО в суде | B34: 19671300
A36: Юрлидер
A37: Наименование | B37: План на 11.05 | C37: Факт с 11.05-17.05 | D37: План на 18.05-24.05
A38: Счета на юр услуги. | B38: =Таблица5052697784[[#This Row],[План на 11.05-17.05]] -> 18 | C38: 25 | D38: 28
A39: Счета на вступления | B39: =Таблица5052697784[[#This Row],[План на 11.05-17.05]] -> 2 | C39: 6 | D39: 2
A40: Сбор юр услуги | B40: =Таблица5052697784[[#This Row],[План на 11.05-17.05]] -> 370000 | C40: 320000 | D40: 400000
A41: Вступления | B41: =Таблица5052697784[[#This Row],[План на 11.05-17.05]] -> 3 | C41: 3 | D41: 3
A43: Барановская
...

Sheet 21 неделя
A1: 21 неделя с 18.05.2026 по 24.05.2026
A2: Ростов | I2: Факт
