Workbook

Sheet Сводка
A1: Строительные компании Ростовской области — итог проверки
A2: 987 компаний из реестра Союза «Строители Ростовской области» (два файла выгрузки). Статус по реестру налоговой (ЕГРЮЛ/ЕГРИП) через Checko — у 987 из 987, проверка — октябрь 2026.
A5: Действуют | C5: Закрываются | E5: Не существуют | G5: Действующих с почтой
A6: =COUNTIF('Все данные'!$B$2:$B$988,"Действует") | C6: =COUNTIF('Все данные'!$B$2:$B$988,"Закрывается") | E6: =COUNTIF('Все данные'!$B$2:$B$988,"Не существует") | G6: =COUNTIFS('Все данные'!$B$2:$B$988,"Действует",'Все данные'!$E$2:$E$988,"?*")
A7: =TEXT(COUNTIF('Все данные'!$B$2:$B$988,"Действует")/COUNTA('Все данные'!$B$2:$B$988),"0%")&" от всех" | C7: ="ликвидация, банкротство" | E7: ="уже закрыты" | G7: ="адреса — лист «Почты»"
A9: Подробно по статусам
A10: Статус в реестре | C10: Что это значит | G10: Компаний | H10: С почтой
A11: Действует | C11: Работает | G11: =COUNTIF('Все данные'!$C$2:$C$988,A11) | H11: =COUNTIFS('Все данные'!$C$2:$C$988,A11,'Все данные'!$E$2:$E$988,"?*")
A12: В процессе ликвидации | C12: Ликвидируется: решение принято, компания ещё в реестре | G12: =COUNTIF('Все данные'!$C$2:$C$988,A12) | H12: =COUNTIFS('Все данные'!$C$2:$C$988,A12,'Все данные'!$E$2:$E$988,"?*")
A13: Банкротство | C13: Идёт банкротство: наблюдение или конкурсное производство | G13: =COUNTIF('Все данные'!$C$2:$C$988,A13) | H13: =COUNTIFS('Все данные'!$C$2:$C$988,A13,'Все данные'!$E$2:$E$988,"?*")
A14: Предстоящее исключение | C14: Налоговая объявила, что исключит компанию из реестра | G14: =COUNTIF('Все данные'!$C$2:$C$988,A14) | H14: =COUNTIFS('Все данные'!$C$2:$C$988,A14,'Все данные'!$E$2:$E$988,"?*")
A15: Ликвидирована | C15: Закрыта: ликвидирована (в том числе после банкротства) | G15: =COUNTIF('Все данные'!$C$2:$C$988,A15) | H15: =COUNTIFS('Все данные'!$C$2:$C$988,A15,'Все данные'!$E$2:$E$988,"?*")
A16: Исключена ФНС | C16: Закрыта: исключена налоговой — недостоверные сведения или не работала | G16: =COUNTIF('Все данные'!$C$2:$C$988,A16) | H16: =COUNTIFS('Все данные'!$C$2:$C$988,A16,'Все данные'!$E$2:$E$988,"?*")
A17: Реорганизована | C17: Закрыта: присоединена к другой компании или преобразована | G17: =COUNTIF('Все данные'!$C$2:$C$988,A17) | H17: =COUNTIFS('Все данные'!$C$2:$C$988,A17,'Все данные'!$E$2:$E$988,"?*")
A18: ИП прекратил деятельность | C18: ИП закрыт | G18: =COUNTIF('Все данные'!$C$2:$C$988,A18) | H18: =COUNTIFS('Все данные'!$C$2:$C$988,A18,'Все данные'!$E$2:$E$988,"?*")
A19: Всего | G19: =SUM(G11:G18) | H19: =SUM(H11:H18)
A21: Как пользоваться
A22: • «Действующие» — работающие компании: почта, телефоны, сайт, руководитель, адрес. Сверху — те, у кого есть почта.
A23: • «Почты» — только действующие компании с почтой: основной адрес и другие. Удобно для рассылки.
A24: • «Закрываются» и «Не существуют» — что произошло с компанией и когда.
A25: • «Все данные» — все столбцы обоих файлов реестра СРО и полный список найденных адресов.
A26: • Телефоны — номер из реестра СРО и номера из Checko без повторов. Почты-опечатки из госзакупок (ofice@, officce@…) с рабочих листов убраны, на листе «Все данные» они остались.
A27: • Руководитель и адрес — из файлов реестра СРО, могли смениться. «Открыть» — карточка компании по ИНН.
A28: • Членство в СРО и работа компании — разные вещи: многие вышли из Союза, но работают.

Sheet Действующие
A1: № | B1: Компания | C1: ИНН | D1: Электронная почта | E1: Телефоны | F1: Сайт | G1: Руководитель (по файлу) | H1: Адрес (по файлу) | I1: Членство в СРО | J1: Примечание | K1: Карточка
A2: 1 | B2: "Донской государственный технический университет", ДГТУ | C2: 6165033136 | D2: udo@donstu.ru; spu-22@donstu.ru; rabota@donstu.ru | E2: +7 (863) 273-86-06, +78632381782, +78632381781, +78632738780 | F2: http://donstu.ru | G2: Ректор Месхи Бесик Чохоевич | H2: 344000, РОССИЯ, Ростовская область, гор. Ростов-на-Дону, пл. Гагарина, дом 1, ком. 242 | I2: член СРО | K2: Открыть
A3: 2 | B3: АО "Газпром газораспределение Элиста" | C3: 0814042970 | D3: office@kalmgaz.ru; office@gpgrelista.ru; priem@ke.rosseti-yug.ru | E3: +7 (84722) 6-28-01, +78474492191, +78474462801, +78472227920, +78472232801 | F3: http://kalmgaz.ru | G3: И.о исполнительного директора Байрхаев Эдуард Валерьевич | H3: 358000, РОССИЯ, Республика Калмыкия, гор. Элиста, ул. Ленина, дом 272 | I3: член СРО | J3: ещё адресов: 12 — лист «Все данные» | K3: Открыть
A4: 3 | B4: АО "Донаэродорстрой" | C4: 6163002069 | D4: oao.dads.tp@yandex.ru; dadcpst@mail.ru; info.su873@gmail.com | E4: +7 (863) 207-66-00 (доб. 416), +74959881125, +78635641243, +78632697810, +78635640902, +78635641752 | F4: http://gcc-don.com | G4: Генеральный директор Зубанов Сергей Анатольевич | H4: 107031, РОССИЯ, Ростовская область, гор. Ростов-на-Дону, Страстной бульвар, дом 8 А, этаж 4, ком. 14-23 | I4: прекращено 29.10.2019 | J4: ещё адресов: 1 — лист «Все данные» | K4: Открыть
A5: 4 | B5: АО "ККПД" | C5: 6168000805 | D5: aokkpd@kkpd.ru | E5: +7 (863) 201-69-80, +78632226412, +78632788094, +78632788092, +78632254333 | F5: http://zaokkpd.aaanet.ru | G5: Генеральный директор Павлов Евгений Александрович | H5: 344016, РОССИЯ, Ростовская область, гор. Ростов-на-Дону, переулок 1-й Машиностроительный, дом 5 | I5: член СРО | K5: Открыть
A6: 5 | B6: АО "КЭМ" | C6: 6163013712 | D6: oaokem@inbox.ru; donfao@donpac.ru | E6: +7 (863) 266-61-86, +78639277845, +78632654222, +78652956859 | F6: http://pnf.aaanet.ru | G6: Генеральный директор Бабаев Геннадий Андреевич | H6: 344006, РОССИЯ, Ростовская область, гор. Ростов-на-Дону, пр. Чехова, дом 56 | I6: член СРО | K6: Открыть
A7: 6 | B7: АО "Мир Чудес" | C7: 6161041979 | D7: rogress-sochi@yandex.ru; brest111111@yandex.ru | E7: +7 (938) 110-69-92, +79282611523 | G7: Генеральный директор Селюжицкий Антон Антонович | H7: 344002, РОССИЯ, Ростовская область, гор. Ростов-на-Дону, ул. Ченцова, дом 15, офис 1 | I7: член СРО | K7: Открыть
A8: 7 | B8: АО "МКС - Дон" | C8: 6164102690 | D8: dor-yg@yandex.ru | E8: +7 (863) 207-66-00 доб. 416, +78632904767 | G8: Генеральный директор Лукьянов Василий Владимирович | H8: 344039, РОССИЯ, Ростовская область, гор. Ростов-на-Дону, ул. Курская, дом 18 А, ком. 3 | I8: прекращено | K8: Открыть
A9: 8 | B9: АО "РОСТОВГАЗСТРОЙ" | C9: 6163007765 | D9: rgsteh@donpac.ru; rostovgazstroj@mail.ru; rgspto@donpac.ru | E9: +7 (863) 240-50-34, +78639223964, +78632401738, +78639223772, +78632401634 | G9: Генеральный директор Пантелишин Владимир Степанович | H9: 344002, РОССИЯ, Ростовская область, г.Ростов-на-Дону, ул.Московская, 79 | I9: член СРО | J9: ещё адресов: 2 — лист «Все данные» | K9: Открыть
A10: 9 | B10: АО "Ростовское" | C10: 6165155494 | D10: rostovskoe@v-k-b.ru; aorostovckoe@mail.ru | E10: +7 (863) 206-12-15, +78632268088, +78003337111, +78612740773 | F10: http://oaorostovskoe.ru | G10: Генеральный директор Степура Марат Юрьевич | H10: 344010, РОССИЯ, Ростовская область, гор. Ростов-на-Дону, ул. Уланская, дом 8, корпус А | I10: прекращено | J10: ещё адресов: 1 — лист «Все данные» | K10: Открыть
A11: 10 | B11: АО "СМУ - Дондорстрой" | C11: 6164248080 | D11: smy-dds@yandex.ru | E11: +7 (863) 269-78-10, +78633202021 | G11: Генеральный директор Никоненко Дмитрий Николаевич | H11: 344000, РОССИЯ, Ростовская область, гор. Ростов-на-Дону, пр-кт Ворошиловский, зд. 46/176 | I11: член СРО | J11: идёт реорганизация | K11: Открыть
A12: 11 | B12: АО СЗ "Конверсия" | C12: 6163103892 | D12: ugss00@mail.ru; 79281098709@yandex.ru | E12: +7 (863) 201-70-06, +78632506015, +78632420801, +78632902323, +78632666018, +79281767556 | G12: Директор Хайбулаев Шамхалдибир Алиевич | H12: 344029, РОССИЯ, Ростовская область, гор. Ростов-на-Дону, ул. 1-й Конной Армии, дом 13 В, строение 2 | I12: член СРО | K12: Открыть
A13: 12 | B13: ГБУ РО "Ростовоблстройзаказчик" | C13: 6163099188 | D13: gu.rosz@yandex.ru; gu.rosz@rambler.ru; d74060@yandex.ru | E13: +7 (863) 253-07-08, +78632535460, +78632534197 | F13: http://rosz61.ru | G13: Директор Мищенко Сергей Николаевич | H13: 344050, РОССИЯ, г.Ростов-на-Дону, ул.Социалистическая, 112 | I13: прекращено 06.06.2017 | J13: ещё адресов: 1 — лист «Все данные» | K13: Открыть
A14: 13 | B14: ЗАО "АМУС" | C14: 2302008401 | D14: zao.amus@mail.ru | E14: +7 (861) 375-33-96, +78613763396, +78613753421, +78613753139 | F14: http://amus.com.ru | G14: Инженер по подготовке производства Митякин Анатолий Анатольевич | H14: 352922, РОССИЯ, г.Армавир, ул.Кропоткина, 1 | I14: нет данных | K14: Открыть
A15: 14 | B15: ЗАО "Водавтоматика" | C15: 6141003559 | D15: dvs@donvodservis.ru | E15: +7 (863) 545-83-83, +78635450501 | G15: Директор Желенков Александр Дмитриевич | H15: 346880, РОССИЯ, г.Батайск, ул.Фермерская, 27 | I15: прекращено 20.10.2015 | K15: Открыть
A16: 15 | B16: ЗАО "ГРАЖДАНПРОМСТРОЙ" | C16: 6164074299 | D16: promstroiru@yandex.ru | E16: +7 (863) 280-05-12, +79612935577 | G16: Генеральный директор Афанасьев Виктор Иванович | H16: 344022, РОССИЯ, г.Ростов-на-Дону, ул.Московская, 71, офис 22 | I16: прекращено 16.02.2017 | K16: Открыть
A17: 16 | B17: ЗАО "ПМК-18" | C17: 6147006242 | D17: pmk-18@mail.ru; pmk18buhg@mail.ru | E17: +7 (863) 657-29-92, +78636552992, +78636573601 | G17: Генеральный директор Ким Алексей Олегович | H17: 347800, РОССИЯ, Ростовская область, г.Каменск-Шахтинский, ул.Халтурина, 40 | I17: член СРО | K17: Открыть
A18: 17 | B18: ЗАО "ЭЛИНА" | C18: 6165000878 | D18: zao-elina@mail.ru; elina@yandex.ru | E18: +7 (863) 290-56-67, +78632995593, +79085186184, +78632012526, +78632905668, +78632981362 | G18: Директор Жолобов Алексей Владимирович | H18: 344065, РОССИЯ, г.Ростов-на-Дону, пр. Стачки, 200/2 | I18: прекращено 31.03.2014 | J18: ещё адресов: 1 — лист «Все данные» | K18: Открыть
A19: 18 | B19: ЗАО "Южтехмонтаж" | C19: 6164100492 | D19: utm@utmdon.ru; or@utmdon.ru | E19: +7 (863) 240-82-62, +78632408704, +78632407081, +78464370920, +78632320246 | G19: Генеральный директор Свитенко Виталий Васильевич | H19: 344007, РОССИЯ, Ростовская область, г.Ростов-на-Дону, ул.Социалистическая, 60 | I19: член СРО | K19: Открыть
A20: 19 | B20: ИП Авитиков Вадим Сукратович | C20: 616617926902 | D20: avitikov.v@mail.ru | E20: +7 (961) 422-71-11 | I20: член СРО | K20: Открыть
A21: 20 | B21: ИП Айдинов Рустам Мейданалиевич | C21: 611804113030 | D21: aydinov.89@bk.ru | E21: +7 (906) 324-44-49 | G21: Айдинов Рустам Мейданалиевич | I21: член СРО | K21: Открыть
A22: 21 | B22: ИП Амирханян Сергей Саркисович | C22: 614208510755 | D22: artprintbk@mail.ru | E22: +7 (928) 612-33-32 | G22: Амирханян Сергей Саркисович | I22: прекращено | K22: Открыть
A23: 22 | B23: ИП Аракелян Эдгар Артушович | C23: 616118197242 | D23: edegar.arakelyan@yandex.ru | E23: +7 (938) 127-40-74 | G23: Аракелян Эдгар Артушович | I23: член СРО | K23: Открыть
A24: 23 | B24: ИП Береза Инна Сергеевна | C24: 616405031226 | D24: 79185074947@yandex.ru | E24: +7 (928) 755-09-09 | G24: Не хочет говорить | I24: прекращено | K24: Открыть
A25: 24 | B25: ИП Близнюков Валерий Герасимович | C25: 615412848962 | D25: ugstroisnab@bk.ru | E25: +7 (928) 125-65-50 | G25: Близнюков Валерий Герасимович | I25: член СРО | K25: Открыть
A26: 25 | B26: ИП Гайдаров Назим Мавлудович | C26: 610304355840 | D26: sm-yug@bk.ru | E26: +7 (903) 489-52-39 | G26: Гайдаров Назим Мавлудович | I26: прекращено | K26: Открыть
A27: 26 | B27: ИП Гальцев Роман Анатольевич | C27: 615309318231 | D27: rnd.rus@bk.ru | E27: +7 (928) 279-55-88 | I27: член СРО | K27: Открыть
A28: 27 | B28: ИП Гончаров Александр Александрович | C28: 616612899067 | D28: aladdin13@yandex.ru | E28: +7 (908) 506-08-32 | I28: член СРО | K28: Открыть
A29: 28 | B29: ИП Дрябо Виталий Владимирович | C29: 616711518330 | D29: 79185145798@yandex.ru | E29: +7 (918) 514-57-98 | I29: член СРО | K29: Открыть
A30: 29 | B30: ИП Ермишин Руслан Маратович | C30: 616712899832 | D30: ruslan_ermishin@mail.ru | E30: +7 (928) 123-65-30 | G30: Ермишин Руслан Маратович | I30: член СРО | K30: Открыть
A31: 30 | B31: ИП Захаров Дмитрий Николаевич | C31: 615103968003 | D31: oks-novshah@mail.ru | E31: +7 (908) 190-92-47 | I31: член СРО | K31: Открыть
A32: 31 | B32: ИП Ильчук Татьяна Эдуардовна | C32: 232525732620 | D32: 4107147@mail.ru | E32: +7 (918) 590-15-03 | G32: Ильчук Татьяна Эдуардовна | I32: член СРО | K32: Открыть
A33: 32 | B33: ИП Карпенко Анастасия Викторовна | C33: 262306955510 | D33: avk-fermer@yandex.ru | E33: +7 (863) 209-86-13 | G33: Карпенко Анастасия Викторовна | I33: нет данных | J33: ИП перерегистрирован (новый ОГРНИП) | K33: Открыть
A34: 33 | B34: ИП Ларцев Василий Васильевич | C34: 616500747080 | D34: asbuo@yandex.ru | E34: +7 (918) 565-65-44 | G34: Ларцев Василий Васильевич | I34: член СРО | K34: Открыть
A35: 34 | B35: ИП Ляшенко Геннадий Николаевич | C35: 616831688171 | D35: yuexcentr@yandex.ru | E35: +7 (863) 232-98-04 | I35: прекращено 26.04.2011 | K35: Открыть
A36: 35 | B36: ИП Мацаков Николай Васильевич | C36: 610100305016 | D36: nina.vasilevna2012@yandex.ru | E36: +7 (903) 43-44-539 | G36: Мацаков Николай Васильевич | I36: прекращено | K36: Открыть
A37: 36 | B37: ИП Медкова Ирина Васильевна | C37: 614903048557 | D37: medkowa2016@yandex.ru; sheplstw@gmail.com | E37: +7 (914) 717-63-56 | I37: член СРО | K37: Открыть
A38: 37 | B38: ИП Мезин Антон Геннадьевич | C38: 616113517322 | D38: c20xe@ya.ru | E38: +7 (928) 964-60-85 | G38: Мезин Антон Геннадьевич | I38: член СРО | K38: Открыть
A39: 38 | B39: ИП Мисюк Сергей Александрович | C39: 616600687420 | D39: sergej.libra@gmail.com | E39: +7 (989) 711-99-18 | G39: Мисюк Сергей Александрович | I39: член СРО | K39: Открыть
A40: 39 | B40: ИП Михай Диана Юрьевна | C40: 615433323370 | D40: bonij66@mail.ru | E40: +7 (950) 865-82-81 | I40: член СРО | K40: Открыть
...

Sheet Почты
A1: № | B1: Компания | C1: ИНН | D1: Основная почта | E1: Другие адреса | F1: Телефоны | G1: Сайт | H1: Карточка
A2: 1 | B2: "Донской государственный технический университет", ДГТУ | C2: 6165033136 | D2: udo@donstu.ru | E2: spu-22@donstu.ru; rabota@donstu.ru | F2: +7 (863) 273-86-06, +78632381782, +78632381781, +78632738780 | G2: http://donstu.ru | H2: Открыть
A3: 2 | B3: АО "Газпром газораспределение Элиста" | C3: 0814042970 | D3: office@kalmgaz.ru | E3: office@gpgrelista.ru; priem@ke.rosseti-yug.ru | F3: +7 (84722) 6-28-01, +78474492191, +78474462801, +78472227920, +78472232801 | G3: http://kalmgaz.ru | H3: Открыть
A4: 3 | B4: АО "Донаэродорстрой" | C4: 6163002069 | D4: oao.dads.tp@yandex.ru | E4: dadcpst@mail.ru; info.su873@gmail.com | F4: +7 (863) 207-66-00 (доб. 416), +74959881125, +78635641243, +78632697810, +78635640902, +78635641752 | G4: http://gcc-don.com | H4: Открыть
A5: 4 | B5: АО "ККПД" | C5: 6168000805 | D5: aokkpd@kkpd.ru | F5: +7 (863) 201-69-80, +78632226412, +78632788094, +78632788092, +78632254333 | G5: http://zaokkpd.aaanet.ru | H5: Открыть
A6: 5 | B6: АО "КЭМ" | C6: 6163013712 | D6: oaokem@inbox.ru | E6: donfao@donpac.ru | F6: +7 (863) 266-61-86, +78639277845, +78632654222, +78652956859 | G6: http://pnf.aaanet.ru | H6: Открыть
A7: 6 | B7: АО "Мир Чудес" | C7: 6161041979 | D7: rogress-sochi@yandex.ru | E7: brest111111@yandex.ru | F7: +7 (938) 110-69-92, +79282611523 | H7: Открыть
A8: 7 | B8: АО "МКС - Дон" | C8: 6164102690 | D8: dor-yg@yandex.ru | F8: +7 (863) 207-66-00 доб. 416, +78632904767 | H8: Открыть
A9: 8 | B9: АО "РОСТОВГАЗСТРОЙ" | C9: 6163007765 | D9: rgsteh@donpac.ru | E9: rostovgazstroj@mail.ru; rgspto@donpac.ru | F9: +7 (863) 240-50-34, +78639223964, +78632401738, +78639223772, +78632401634 | H9: Открыть
A10: 9 | B10: АО "Ростовское" | C10: 6165155494 | D10: rostovskoe@v-k-b.ru | E10: aorostovckoe@mail.ru | F10: +7 (863) 206-12-15, +78632268088, +78003337111, +78612740773 | G10: http://oaorostovskoe.ru | H10: Открыть
A11: 10 | B11: АО "СМУ - Дондорстрой" | C11: 6164248080 | D11: smy-dds@yandex.ru | F11: +7 (863) 269-78-10, +78633202021 | H11: Открыть
A12: 11 | B12: АО СЗ "Конверсия" | C12: 6163103892 | D12: ugss00@mail.ru | E12: 79281098709@yandex.ru | F12: +7 (863) 201-70-06, +78632506015, +78632420801, +78632902323, +78632666018, +79281767556 | H12: Открыть
A13: 12 | B13: ГБУ РО "Ростовоблстройзаказчик" | C13: 6163099188 | D13: gu.rosz@yandex.ru | E13: gu.rosz@rambler.ru; d74060@yandex.ru | F13: +7 (863) 253-07-08, +78632535460, +78632534197 | G13: http://rosz61.ru | H13: Открыть
A14: 13 | B14: ЗАО "АМУС" | C14: 2302008401 | D14: zao.amus@mail.ru | F14: +7 (861) 375-33-96, +78613763396, +78613753421, +78613753139 | G14: http://amus.com.ru | H14: Открыть
A15: 14 | B15: ЗАО "Водавтоматика" | C15: 6141003559 | D15: dvs@donvodservis.ru | F15: +7 (863) 545-83-83, +78635450501 | H15: Открыть
A16: 15 | B16: ЗАО "ГРАЖДАНПРОМСТРОЙ" | C16: 6164074299 | D16: promstroiru@yandex.ru | F16: +7 (863) 280-05-12, +79612935577 | H16: Открыть
A17: 16 | B17: ЗАО "ПМК-18" | C17: 6147006242 | D17: pmk-18@mail.ru | E17: pmk18buhg@mail.ru | F17: +7 (863) 657-29-92, +78636552992, +78636573601 | H17: Открыть
A18: 17 | B18: ЗАО "ЭЛИНА" | C18: 6165000878 | D18: zao-elina@mail.ru | E18: elina@yandex.ru | F18: +7 (863) 290-56-67, +78632995593, +79085186184, +78632012526, +78632905668, +78632981362 | H18: Открыть
A19: 18 | B19: ЗАО "Южтехмонтаж" | C19: 6164100492 | D19: utm@utmdon.ru | E19: or@utmdon.ru | F19: +7 (863) 240-82-62, +78632408704, +78632407081, +78464370920, +78632320246 | H19: Открыть
A20: 19 | B20: ИП Авитиков Вадим Сукратович | C20: 616617926902 | D20: avitikov.v@mail.ru | F20: +7 (961) 422-71-11 | H20: Открыть
A21: 20 | B21: ИП Айдинов Рустам Мейданалиевич | C21: 611804113030 | D21: aydinov.89@bk.ru | F21: +7 (906) 324-44-49 | H21: Открыть
A22: 21 | B22: ИП Амирханян Сергей Саркисович | C22: 614208510755 | D22: artprintbk@mail.ru | F22: +7 (928) 612-33-32 | H22: Открыть
A23: 22 | B23: ИП Аракелян Эдгар Артушович | C23: 616118197242 | D23: edegar.arakelyan@yandex.ru | F23: +7 (938) 127-40-74 | H23: Открыть
A24: 23 | B24: ИП Береза Инна Сергеевна | C24: 616405031226 | D24: 79185074947@yandex.ru | F24: +7 (928) 755-09-09 | H24: Открыть
A25: 24 | B25: ИП Близнюков Валерий Герасимович | C25: 615412848962 | D25: ugstroisnab@bk.ru | F25: +7 (928) 125-65-50 | H25: Открыть
A26: 25 | B26: ИП Гайдаров Назим Мавлудович | C26: 610304355840 | D26: sm-yug@bk.ru | F26: +7 (903) 489-52-39 | H26: Открыть
A27: 26 | B27: ИП Гальцев Роман Анатольевич | C27: 615309318231 | D27: rnd.rus@bk.ru | F27: +7 (928) 279-55-88 | H27: Открыть
A28: 27 | B28: ИП Гончаров Александр Александрович | C28: 616612899067 | D28: aladdin13@yandex.ru | F28: +7 (908) 506-08-32 | H28: Открыть
A29: 28 | B29: ИП Дрябо Виталий Владимирович | C29: 616711518330 | D29: 79185145798@yandex.ru | F29: +7 (918) 514-57-98 | H29: Открыть
A30: 29 | B30: ИП Ермишин Руслан Маратович | C30: 616712899832 | D30: ruslan_ermishin@mail.ru | F30: +7 (928) 123-65-30 | H30: Открыть
A31: 30 | B31: ИП Захаров Дмитрий Николаевич | C31: 615103968003 | D31: oks-novshah@mail.ru | F31: +7 (908) 190-92-47 | H31: Открыть
... A36: 35 | B36: ИП Мацаков Николай Васильевич | C36: 610100305016 | D36: nina.vasilevna2012@yandex.ru | F36: +7 (903) 43-44-539 | H36: Открыть
A37: 36 | B37: ИП Медкова Ирина Васильевна | C37: 614903048557 | D37: medkowa2016@yandex.ru | E37: sheplstw@gmail.com | F37: +7 (914) 717-63-56 | H37: Открыть
A38: 37 | B38: ИП Мезин Антон Геннадьевич | C38: 616113517322 | D38: c20xe@ya.ru | F38: +7 (928) 964-60-85 | H38: Открыть
A39: 38 | B39: ИП Мисюк Сергей Александрович | C39: 616600687420 | D39: sergej.libra@gmail.com | F39: +7 (989) 711-99-18 | H39: Открыть
A40: 39 | B40: ИП Михай Диана Юрьевна | C40: 615433323370 | D40: bonij66@mail.ru | F40: +7 (950) 865-82-81 | H40: Открыть
A41: 40 | B41: ИП Петров Игорь Леонидович | C41: 361703608753 | D41: petrov_i_l@bk.ru | F41: +7 (918) 515-48-48 | H41: Открыть
A42: 41 | B42: ИП Раксин Виктор Пантелеевич | C42: 613100049689 | D42: raskin@mail.ru | F42: +7 (928) 176-62-28 | H42: Открыть
A43: 42 | B43: ИП Ребриев Владимир Александрович | C43: 614310886597 | D43: p1251@yandex.ru | F43: +7 (918) 551-84-25 Владимир | H43: Открыть
A44: 43 | B44: ИП Семёнов Никита Иванович | C44: 616132709510 | D44: n.semenov1009@yandex.ru | F44: +7 (918) 590-15-03 | H44: Открыть
...

Sheet Закрываются
A1: № | B1: Компания | C1: ИНН | D1: Что происходит | E1: С какой даты | F1: Электронная почта | G1: Телефоны | H1: Руководитель (по файлу) | I1: Карточка
A2: 1 | B2: АО "Водоканал" | C2: 6153023510 | D2: Банкротство: конкурсное производство | F2: vodokanal.salsk@inbox.ru; vodokanal@salsk.donpak.ru; adm-slk@salsk.donpac.ru | G2: +7 (8637) 25-07-38, +78637270176, +78867251663, +78637251663, +78637272843 | H2: Конкурсный управляющий Реук Андрей Михайлович | I2: Открыть
A3: 2 | B3: АО "Ростов - ЦентрСтрой" | C3: 6163045224 | D3: Банкротство: конкурсное производство | G3: +7 (863) 227-32-88, +78632670490 | H3: Генеральный директор Коробченко Николай Николаевич | I3: Открыть
A4: 3 | B4: ООО "АиК" | C4: 6161044592 | D4: Банкротство: конкурсное производство | G4: +7 (863) 310-05-00, +78632787071, +79563232041 | H4: Конкурсный управляющий Землянских Ангелина Сергеевна | I4: Открыть
A5: 4 | B5: ООО "АйТиТех" | C5: 6166109998 | D5: Банкротство: конкурсное производство | G5: +7 (800) 5118261, +79897053546 | H5: Генеральный директор Цветов Алексей Сергеевич | I5: Открыть
A6: 5 | B6: ООО "Альтернативные Системы Телекоммуникаций" | C6: 6163123708 | D6: Банкротство: конкурсное производство | F6: ooo_ast_rostov@mail.ru | G6: +7 (909) 408-42-84, +78632623635, +78632353399 | H6: Генеральный директор Прикмета Ирина Викторовна | I6: Открыть
A7: 6 | B7: ООО "АЭМ Сервис" | C7: 6161079651 | D7: Банкротство: конкурсное производство | F7: rostov@groupaem.ru; aseevivan@groupaem.ru; titov.os@gmail.com | G7: +7 (863) 204-21-29, +79885811954, +79882563043, +79897000044, +78612011618 | H7: Генеральный директор Асеев Иван Владимирович | I7: Открыть
A8: 7 | B8: ООО "Давлад" | C8: 6167122790 | D8: Банкротство: конкурсное производство | F8: davlad.01@mail.ru | G8: +7 (863) 261-32-20, +78632514445, +79044430230 | H8: Генеральный директор Ушаков Руслани Юрьевич | I8: Открыть
A9: 8 | B9: ООО "Движение" | C9: 6166122205 | D9: Банкротство: конкурсное производство | F9: ooo-dvlzhenie@yandex.ru; 4312610@gmail.com; 2635002@mail.ru | G9: +7 (928) 777-99-83, +79895533731, +78633180055, +79289099011, +78638822028, +78633150055 | H9: Генеральный директор Гетьман Михаил Анатольевич | I9: Открыть
A10: 9 | B10: ООО "ДОНСТРОЙ" | C10: 6155070516 | D10: Банкротство: конкурсное производство | F10: 263779@mail.ru | G10: +7 (918) 585-13-40, +78636263779 | H10: Директор Мезев Дмитрий Анатольевич | I10: Открыть
A11: 10 | B11: ООО "ДРСУ" | C11: 6163150807 | D11: Банкротство: конкурсное производство | F11: drsu2016@list.ru; drsu@mail.ru | G11: +7 (918) 555-09-61, +79282797669, +78632990224, +78632266238, +79515173416 | H11: Генеральный директор Сибилев Константин Юрьевич | I11: Открыть
A12: 11 | B12: ООО "Концерн-Строй" | C12: 6141055067 | D12: Банкротство: конкурсное производство | F12: ks@collecshn.ru | G12: +7 (863) 301-79-57, +78632040454, +79188590966 | H12: Генеральный директор Воробьев Алексей Валерьевич | I12: Открыть
A13: 12 | B13: ООО "МОНОЛИТТРЕСТ" | C13: 6164106857 | D13: Банкротство: конкурсное производство | F13: monolittrest@mail.ru | G13: +7 (863) 207-81-37, +79188574761 | H13: Директор Московцев Тимофей Дмитриевич | I13: Открыть
A14: 13 | B14: ООО "НЭСК ЮГА" | C14: 6154148336 | D14: Банкротство: конкурсное производство | F14: nesk.yuga@mail.ru | G14: +7 (961) 296-91-05, +77281195926, +79281891713, +79381326475, +79185696162 | H14: Генеральный директор Фоменко Евгения Александровна | I14: Открыть
A15: 14 | B15: ООО "ОКС" Г. НОВОШАХТИНСКА | C15: 6151018554 | D15: Банкротство: конкурсное производство | F15: oks@novshah.donpac.ru | G15: +7 (863) 692-64-60 | H15: Конкурсный управляющий Гайдунков Роман Владимирович | I15: Открыть
A16: 15 | B16: ООО "Оникс" | C16: 6154126540 | D16: Банкротство: конкурсное производство | F16: info@tag-onix.ru | G16: +7 (928) 172-22-99, +7(8634) 318-575, +78634365002 | H16: Директор Беленко Сергей Юрьевич | I16: Открыть
A17: 16 | B17: ООО "Промэнерго" | C17: 6163107061 | D17: Банкротство: конкурсное производство | G17: +7 (928) 102-60-68, +79281850941, +78632504299 | H17: Директор Величкин Михаил Николаевич | I17: Открыть
A18: 17 | B18: ООО "Р.С.Альянс" | C18: 6154014117 | D18: Банкротство: конкурсное производство | G18: +7 (863) 431-29-46, +78634625118, +78634392350 | H18: Директор Маркарьян Хачатур Хоренович | I18: Открыть
A19: 18 | B19: ООО "РостовСервисСтрой" | C19: 6164253481 | D19: Банкротство: конкурсное производство | F19: pcc2006@mail.ru; 2006@mail.ru | G19: +7 (863) 234-92-11, +78632203717, +79034350872 | H19: Директор Сабельников Николай Павлович | I19: Открыть
A20: 19 | B20: ООО "РПА" | C20: 6141032180 | D20: Банкротство: конкурсное производство | F20: buh@zavod-rpa.ru; info@zavod-rpa.ru | G20: +7 (863) 303-41-66, +78633225455 | H20: Генеральный директор Маланчук Лариса Анатольевна | I20: Открыть
A21: 20 | B21: ООО "Сети - Строй" | C21: 3443125004 | D21: Банкротство: конкурсное производство | F21: seti.stroy@mail.ru | G21: +7 (8442) 78-64-70, +78632247704, +79275331669 | H21: Генеральный директор Фоменко Игорь Николаевич | I21: Открыть
A22: 21 | B22: ООО "СИЭРЭС" | C22: 6166098390 | D22: Банкротство: конкурсное производство | F22: vma@c-r-s.ru | G22: +7 (863) 301-08-05, +78633010806, +79282266994 | H22: Директор Верхотина Мария Александровна | I22: Открыть
A23: 22 | B23: ООО "СК СтройКом" | C23: 6163125381 | D23: Банкротство: конкурсное производство | F23: sk-stroikom@mail.ru; sk-stroikom.tp@mail.ru | G23: +7 (863) 263-47-12, +78632105015, +78632105075, +79287511285 | H23: Генеральный директор Высоцкий Константин Викторович | I23: Открыть
A24: 23 | B24: ООО "Скиф-Строй" | C24: 6164300332 | D24: Банкротство: конкурсное производство | G24: +7 (863) 219-28-41, +78632623988, +79034048005 | H24: Генеральный директор Шкуропадский Александр Герасимович | I24: Открыть
A25: 24 | B25: ООО "Союз Архстрой" | C25: 6165099289 | D25: Банкротство: конкурсное производство | F25: souzarchstoy@yandex.ru | G25: +7 (863) 232-98-04, +78632180681, +78632327223, +78632315497, +79811744627 | H25: Директор Ляшенко Геннадий Николаевич | I25: Открыть
A26: 25 | B26: ООО "СпецГарант" | C26: 6150074845 | D26: Банкротство: конкурсное производство | F26: tara_ug@mail.ru; nata.spetsgarant@mail.ru; lisa09.82@mail.ru | G26: +7 (918) 854-19-60, +79045087015 | H26: Директор Усенко Наталья Витальевна | I26: Открыть
A27: 26 | B27: ООО "Спецстрой" | C27: 6165559810 | D27: Банкротство: конкурсное производство | F27: spetstroi@list.ru | G27: +7 (951) 517-34-16, +78632990224, +79282790313, +78632990294, +79281100139 | H27: Генеральный директор Степанов Георгий Тигранович | I27: Открыть
A28: 27 | B28: ООО "Строительная Компания Югэнергоспецстрой" | C28: 6165079194 | D28: Банкротство: конкурсное производство | F28: sk_uess@bk.ru | G28: +7 (863) 256-49-59, +78632969989, +78632072419 | H28: Директор Гузиков Евгений Анатольевич | I28: Открыть
A29: 28 | B29: ООО "Стройинжиниринг" | C29: 6166069880 | D29: Банкротство: конкурсное производство | G29: +7 (863) 200-22-99, +78632689600, +78632681436, +78632002780, +78632443456 | H29: Директор Дмитриев Евгений Вячеславович | I29: Открыть
A30: 29 | B30: ООО "СТЭК" | C30: 6162083957 | D30: Банкротство: конкурсное производство | F30: stekrostov@yandex.ru | G30: +7 (918) 894-87-05 | H30: Директор Фадеева Ольга Владимировна | I30: Открыть
A31: 30 | B31: ООО "Экострой-Дон" | C31: 6125028860 | D31: Банкротство: конкурсное производство | F31: esd-rostov@yandex.ru; mbdoy3.shahty@yandex.ru; rostov@yandex.ru | G31: +7 (8636) 20-01-54, +79381262241, +78638821142, +78863200154, +78003025333 | H31: Генеральный директор Минина Зухра Болатбековна | I31: Открыть
A32: 31 | B32: ООО "ЮАХ - сервис" | C32: 6166091420 | D32: Банкротство: конкурсное производство | F32: yuahservis@yandex.ru; 2635002@mail.ru | G32: +7 (863) 229-90-11, +79287778813, +78633089507 | H32: Директор Куряков Денис Владимирович | I32: Открыть
A33: 32 | B33: ООО "Южная трибуна" | C33: 6161081523 | D33: Банкротство: конкурсное производство | G33: +7 (906) 728-91-66 | H33: Генеральный директор Фролов Александр Владимирович | I33: Открыть
A34: 33 | B34: ООО "ЮСК" | C34: 6165137664 | D34: Банкротство: конкурсное производство | F34: els98e@mail.ru | G34: +7 (928) 771-87-77, +78632807802, +78632807804, +78632904636, +78632807803, +79604663454 | H34: Директор Полин Сергей Александрович | I34: Открыть
A35: 34 | B35: ООО "ЮСК" | C35: 6163095507 | D35: Банкротство: конкурсное производство | F35: usk2008@list.ru | G35: +7 (928) 771-87-77, +78632001458, +78632001463, +79381622997, +79185309026 | H35: Директор Орлов Алексей Викторович | I35: Открыть
A36: 35 | B36: ООО СК "Капитал" | C36: 6163131201 | D36: Банкротство: конкурсное производство | F36: info@sk-kapital.com; info@sk-stroikov.ru; rosmail@inbox.ru | G36: +7 (863) 201-80-72, +78632669715 | H36: Директор Каргатов Иван Михайлович | I36: Открыть
A37: 36 | B37: ООО СК "КИТОВРАС" | C37: 6145004730 | D37: Банкротство: конкурсное производство | F37: ed@dontextil.ru | G37: +7 (929) 802-36-16, +78636833759 | H37: Генеральный директор Щипелев Виталий Вячеславович | I37: Открыть
A38: 37 | B38: ООО "Монолит - Юг" | C38: 6155012602 | D38: Банкротство: наблюдение | F38: monolit-161@mail.ru | G38: +7 (8636) 27-92-21, +78007070161, +78005515311, +78636288768, +78636221712, +78636279220 | H38: Директор Кильдюшев Павел Васильевич | I38: Открыть
A39: 38 | B39: ООО "Полигон-Аксай" | C39: 6102067887 | D39: Банкротство: наблюдение | F39: poligon-aksay@mail.ru | G39: +7 (988) 941-65-95, +78635044723 | H39: Директор Малофеев Дмитрий Сергеевич | I39: Открыть
A40: 39 | B40: ООО "Промкомплекс "Барс" | C40: 6154571076 | D40: Банкротство: наблюдение | F40: office.pkbars@gmail.com; tgkonoplya@rambler.ru; oppk_bars@mail.ru | G40: +7 (8632) 36-03-94, +78633089325, +79897144401, +79780491408 | H40: Генеральный директор Конопля Сергей Сергеевич | I40: Открыть
...

Sheet Не существуют
A1: № | B1: Компания | C1: ИНН | D1: Как прекратила работу | E1: Дата | F1: Членство в СРО | G1: Карточка
A2: 1 | B2: ООО "РОСТОВРЕГИОНСТРОЙ" | C2: 6164105910 | D2: Ликвидирована | E2: 46248 | F2: прекращено | G2: Открыть
A3: 2 | B3: ООО "ПРАЙМ" | C3: 6164128184 | D3: Ликвидирована | E3: 46246 | F3: член СРО | G3: Открыть
A4: 3 | B4: ООО "ДОН - две СТОЛИЦЫ" | C4: 6164306831 | D4: Ликвидирована | E4: 45882 | F4: прекращено | G4: Открыть
A5: 4 | B5: ООО "Райсвет" | C5: 6122002197 | D5: Ликвидирована | E5: 45722 | F5: прекращено | G5: Открыть
A6: 5 | B6: ООО "ВЕКТОР" | C6: 6164129212 | D6: Ликвидирована | E6: 45707 | F6: прекращено | G6: Открыть
A7: 6 | B7: ООО "СТРОЙТЕХ" | C7: 6164132575 | D7: Ликвидирована | E7: 45701 | F7: член СРО | G7: Открыть
A8: 7 | B8: ООО "СТРОЙИНЖИНИРИНГ" | C8: 6164132582 | D8: Ликвидирована | E8: 45694 | F8: член СРО | G8: Открыть
A9: 8 | B9: ЗАО "Ростовлифт" | C9: 6165013010 | D9: Ликвидирована | E9: 45667 | F9: член СРО | G9: Открыть
A10: 9 | B10: ООО "СК "Стройзаказчик" | C10: 6141030560 | D10: Ликвидирована | E10: 45639 | F10: прекращено | G10: Открыть
A11: 10 | B11: ООО "ЭЛЕКТРОПРОММОНТАЖ-ЮГ" | C11: 6150093686 | D11: Ликвидирована | E11: 45288 | F11: прекращено | G11: Открыть
A12: 11 | B12: ООО "Стройсервис" | C12: 6101035219 | D12: Ликвидирована | E12: 45226 | F12: прекращено | G12: Открыть
A13: 12 | B13: ООО "ПД Юг" | C13: 6164107530 | D13: Ликвидирована | E13: 44965 | F13: прекращено | G13: Открыть
... A278: 277 | B278: ИП Гордина Людмила Леонидовна | C278: 616502299518 | D278: ИП закрыт | E278: 40637 | F278: прекращено 24.12.2010 | G278: Открыть

Sheet Все данные
A1: № | B1: Итог | C1: Статус в ЕГРЮЛ / ЕГРИП | D1: Дата события | E1: Электронная почта | F1: Телефоны (Checko) | G1: Сайт (Checko) | H1: Наименование (из файла) | I1: Текущее наименование | J1: ИНН | K1: ОГРН / ОГРНИП | L1: Телефон (из файла) | M1: Адрес (из файла) | N1: Руководитель (из файла) | O1: Членство в СРО (по файлу) | P1: Рег. номер в реестре СРО | Q1: Дата вступления в СРО | R1: Решение СРО (по файлу) | S1: Взнос в КФ (по файлу) | T1: Дата гос. регистрации | U1: Полное наименование (из файла) | V1: Где в исходных файлах | W1: Откуда статус | X1: Что сказано в источнике | Y1: Источник | Z1: Перепроверить | AA1: Проверить самому
A2: 1 | B2: Действует | C2: Действует | E2: udo@donstu.ru; spu-22@donstu.ru; rabota@donstu.ru | F2: +78632381782; +78632381781; +78632738780 | G2: http://donstu.ru | H2: "Донской государственный технический университет", ДГТУ | I2: ДОНСКОЙ ГОСУДАРСТВЕННЫЙ ТЕХНИЧЕСКИЙ УНИВЕРСИТЕТ, ДГТУ | J2: 6165033136 | K2: 1026103727847 | L2: +7 (863) 273-86-06 | M2: 344000, РОССИЯ, Ростовская область, гор. Ростов-на-Дону, пл. Гагарина, дом 1, ком. 242 | N2: Ректор Месхи Бесик Чохоевич | O2: член СРО | P2: 230 | Q2: 40354 | T2: 37589 | U2: Федеральное государственное бюджетное образовательное учреждение высшего образования "Донской государственный технический университет" | V2: файл 2, № 772 | W2: Checko | X2: ЕГРЮЛ/ЕГРИП (Checko): «Действует» | Y2: Checko API (ЕГРЮЛ/ЕГРИП), https://checko.ru/search?query=6165033136 | AA2: Открыть
A3: 2 | B3: Действует | C3: Действует | E3: ofice@gpgrelista.ru; tsasmo@yandex.ru; office@grgrelista.ru; officce@gpgrelusta.ru; office@grpgrelista.ru; office@gpgelista.ru; office@gprelista.ru; offce@gpgrelista.ru; ffice@gpgrelista.ru; priem@ke.rosseti-yug.ru; offise@gpgrelista.ru; office@kalmgaz.ru; office@gpgrelista.ru; offic@gpgrelista.ru; priem@ke.rosseti-ung.ru | F3: +78472262801; +78474492191; +78474462801; +78472227920; +78472232801 | G3: http://kalmgaz.ru | H3: АО "Газпром газораспределение Элиста" | I3: АО "ГАЗПРОМ ГАЗОРАСПРЕДЕЛЕНИЕ ЭЛИСТА" | J3: 0814042970 | K3: 1030800746206 | L3: +7 (84722) 6-28-01 | M3: 358000, РОССИЯ, Республика Калмыкия, гор. Элиста, ул. Ленина, дом 272 | N3: И.о исполнительного директора Байрхаев Эдуард Валерьевич | O3: член СРО | P3: 400 | Q3: 42934 | R3: Решение Совета Союза "Строители Ростовской области" №335 от 18.07.2017 г. | S3: 500 000 | T3: 36322 | U3: Акционерное общество "Газпром газораспределение Элиста" | V3: файл 1, № 245 | W3: Checko | X3: ЕГРЮЛ/ЕГРИП (Checko): «Действует» | Y3: Checko API (ЕГРЮЛ/ЕГРИП), https://checko.ru/search?query=0814042970 | AA3: Открыть
A4: 3 | B4: Действует | C4: Действует | E4: oao.dads.tp@yandex.ru; dadcpst@mail.ru; info.su873@gmail.com; info@aodads.ru | F4: +74959881125; +78635641243; +78632697810; +78635640902; +78635641752 | G4: http://gcc-don.com | H4: АО "Донаэродорстрой" | I4: АО "ДОНАЭРОДОРСТРОЙ" | J4: 6163002069 | K4: 1026103158730 | L4: +7 (863) 207-66-00 (доб. 416) | M4: 107031, РОССИЯ, Ростовская область, гор. Ростов-на-Дону, Страстной бульвар, дом 8 А, этаж 4, ком. 14-23 | N4: Генеральный директор Зубанов Сергей Анатольевич | O4: прекращено 29.10.2019 | P4: 380 | Q4: 42929 | T4: 33947 | U4: Акционерное общество по строительству и реконструкции автомобильных дорог и аэродромов | V4: файл 2, № 616 | W4: Checko | X4: ЕГРЮЛ/ЕГРИП (Checko): «Действует» | Y4: Checko API (ЕГРЮЛ/ЕГРИП), https://checko.ru/search?query=6163002069 | AA4: Открыть
A5: 4 | B5: Действует | C5: Действует | E5: aokkpd@kkpd.ru | F5: +78632226412; +78632788094; +78632788092; +78632254333; +78632016980 | G5: http://zaokkpd.aaanet.ru | H5: АО "ККПД" | I5: АО "ККПД" | J5: 6168000805 | K5: 1026104357014 | L5: +7 (863) 201-69-80 | M5: 344016, РОССИЯ, Ростовская область, гор. Ростов-на-Дону, переулок 1-й Машиностроительный, дом 5 | N5: Генеральный директор Павлов Евгений Александрович | O5: член СРО | P5: 442 | Q5: 43069 | R5: Решение Совета Союза "Строители Ростовской области" №370 от 30.11.2017 г. | S5: 1 500 000 | T5: 33947 | U5: Акционерное общество "КОМБИНАТ КРУПНОПАНЕЛЬНОГО ДОМОСТРОЕНИЯ" | V5: файл 1, № 263 | W5: Checko | X5: ЕГРЮЛ/ЕГРИП (Checko): «Действует» | Y5: Checko API (ЕГРЮЛ/ЕГРИП), https://checko.ru/search?query=6168000805 | AA5: Открыть
A6: 5 | B6: Действует | C6: Действует | E6: oaokem@inbox.ru; donfao@donpac.ru | F6: +78639277845; +78632666186; +78632654222; +78652956859 | G6: http://pnf.aaanet.ru | H6: АО "КЭМ" | I6: АО "КЭМ" | J6: 6163013712 | K6: 1026103158597 | L6: +7 (863) 266-61-86 | M6: 344006, РОССИЯ, Ростовская область, гор. Ростов-на-Дону, пр. Чехова, дом 56 | N6: Генеральный директор Бабаев Геннадий Андреевич | O6: член СРО | P6: 407 | Q6: 42944 | T6: 35416 | U6: Акционерное общество "Кавэлектромонтаж" | V6: файл 2, № 799 | W6: Checko | X6: ЕГРЮЛ/ЕГРИП (Checko): «Действует» | Y6: Checko API (ЕГРЮЛ/ЕГРИП), https://checko.ru/search?query=6163013712 | AA6: Открыть
A7: 6 | B7: Действует | C7: Действует | E7: rogress-sochi@yandex.ru; brest111111@yandex.ru | F7: +79381106992; +79282611523 | H7: АО "Мир Чудес" | I7: АО "МИР ЧУДЕС" | J7: 6161041979 | K7: 1056161005900 | L7: +7 (938) 110-69-92 | M7: 344002, РОССИЯ, Ростовская область, гор. Ростов-на-Дону, ул. Ченцова, дом 15, офис 1 | N7: Генеральный директор Селюжицкий Антон Антонович | O7: член СРО | P7: 753 | Q7: 44554 | T7: 38434 | U7: Акционерное общество "Мир Чудес" | V7: файл 2, № 976 | W7: Checko | X7: ЕГРЮЛ/ЕГРИП (Checko): «Действует» | Y7: Checko API (ЕГРЮЛ/ЕГРИП), https://checko.ru/search?query=6161041979 | AA7: Открыть
A8: 7 | B8: Действует | C8: Действует | E8: dor-yg@yandex.ru | F8: +78632904767 | H8: АО "МКС - Дон" | I8: АО "МКС-ДОН" | J8: 6164102690 | K8: 1156196061779 | L8: +7 (863) 207-66-00 доб. 416 | M8: 344039, РОССИЯ, Ростовская область, гор. Ростов-на-Дону, ул. Курская, дом 18 А, ком. 3 | N8: Генеральный директор Лукьянов Василий Владимирович | O8: прекращено | P8: 454 | Q8: 43126 | R8: Решение Совета Союза "Строители Ростовской области" №381 от 26.01.2018 г. | S8: 100 000 | T8: 42284 | U8: Акционерное общество "Монтаж контактной сети - Дон" | V8: файл 1, № 364 | W8: Checko | X8: ЕГРЮЛ/ЕГРИП (Checko): «Действует» | Y8: Checko API (ЕГРЮЛ/ЕГРИП), https://checko.ru/search?query=6164102690 | AA8: Открыть
A9: 8 | B9: Действует | C9: Действует | E9: rostovgazstroj@mail.ru; rgspto@donpac.ru; rqsteh@donpac.ru; rgsteh@dopac.ru; rgsteh@donpac.ru | F9: +78632405034; +78639223964; +78632401738; +78639223772; +78632401634 | H9: АО "РОСТОВГАЗСТРОЙ" | I9: ПАО "РОСТОВГАЗСТРОЙ" | J9: 6163007765 | K9: 1026103164196 | L9: +7 (863) 240-50-34 | M9: 344002, РОССИЯ, Ростовская область, г.Ростов-на-Дону, ул.Московская, 79 | N9: Генеральный директор Пантелишин Владимир Степанович | O9: член СРО | P9: 128 | Q9: 40199 | T9: 37554 | U9: Акционерное общество "РОСТОВГАЗСТРОЙ" | V9: файл 2, № 929 | W9: Checko | X9: ЕГРЮЛ/ЕГРИП (Checko): «Действует» | Y9: Checko API (ЕГРЮЛ/ЕГРИП), https://checko.ru/search?query=6163007765 | AA9: Открыть
A10: 9 | B10: Действует | C10: Действует | E10: rostovskoe@v-k-b.ru; aorostovckoe@mail.ru; rostovckoe2@v-k-b.ru | F10: +78632061215; +78632268088; +78003337111; +78612740773 | G10: http://oaorostovskoe.ru | H10: АО "Ростовское" | I10: АО "РОСТОВСКОЕ" | J10: 6165155494 | K10: 1096165002229 | L10: +7 (863) 206-12-15 | M10: 344010, РОССИЯ, Ростовская область, гор. Ростов-на-Дону, ул. Уланская, дом 8, корпус А | N10: Генеральный директор Степура Марат Юрьевич | O10: прекращено | P10: 303 | Q10: 42727 | R10: Решение Совета Союза "Строители Ростовской области" от 01.07.2017 г. | S10: 800 000 | T10: 39965 | U10: Акционерное общество "Ростовское" | V10: файл 1, № 10 | W10: Checko | X10: ЕГРЮЛ/ЕГРИП (Checko): «Действует» | Y10: Checko API (ЕГРЮЛ/ЕГРИП), https://checko.ru/search?query=6165155494 https://www.list-org.com/company/38391 https://spark-interfax.ru/krasnodarski-krai-krasnodar/ao-rostovskoe-inn-6165155494-ogrn-1096165002229-f85755f3a8ed483cb271b47f64c617ac | AA10: Открыть
A11: 10 | B11: Действует | C11: Действует | E11: smy-dds@yandex.ru | F11: +78633202021 | H11: АО "СМУ - Дондорстрой" | I11: АО "СМУ-ДОНДОРСТРОЙ" | J11: 6164248080 | K11: 1066164171050 | L11: +7 (863) 269-78-10 | M11: 344000, РОССИЯ, Ростовская область, гор. Ростов-на-Дону, пр-кт Ворошиловский, зд. 46/176 | N11: Генеральный директор Никоненко Дмитрий Николаевич | O11: член СРО | P11: 379 | Q11: 42929 | T11: 38827 | U11: Акционерное общество "СМУ - Дондорстрой" | V11: файл 2, № 857 | W11: Checko | X11: ЕГРЮЛ/ЕГРИП (Checko): «Юридическое лицо находится в процессе реорганизации в форме присоединения к нему других юридических лиц»; в процессе реорганизации | Y11: Checko API (ЕГРЮЛ/ЕГРИП), https://checko.ru/search?query=6164248080 | Z11: да | AA11: Открыть
A12: 11 | B12: Действует | C12: Действует | E12: ugss00@mail.ru; 79281098709@yandex.ru | F12: +78632506015; +78632420801; +78632902323; +78632666018; +79281767556 | H12: АО СЗ "Конверсия" | I12: АО СЗ "КОНВЕРСИЯ" | J12: 6163103892 | K12: 1106193004675 | L12: +7 (863) 201-70-06 | M12: 344029, РОССИЯ, Ростовская область, гор. Ростов-на-Дону, ул. 1-й Конной Армии, дом 13 В, строение 2 | N12: Директор Хайбулаев Шамхалдибир Алиевич | O12: член СРО | P12: 693 | Q12: 44274 | R12: Решение Совета Союза "Строители Ростовской области" №612 от 19.03.2021 г. | S12: 500 000 | T12: 40408 | U12: Акционерное общество специализированный застройщик "КОНВЕРСИЯ" | V12: файл 1, № 82 | W12: Checko | X12: ЕГРЮЛ/ЕГРИП (Checko): «Действует» | Y12: Checko API (ЕГРЮЛ/ЕГРИП), https://checko.ru/search?query=6163103892 https://spark-interfax.ru/rostovskaya-oblast-rostov-na-donu/ao-konversiya-inn-6163103892-ogrn-1106193004675-b227fe1e766b4595ac2ac620bbb08391 https://digital.mchs.gov.ru/fgpn/license/61-06-2025-000735/pdf | AA12: Открыть
A13: 12 | B13: Действует | C13: Действует | E13: gu.rosz@yandex.ru; gu.rosz@rambler.ru; d74060@yandex.ru; rostov-0874@mail.ru | F13: +78632535460; +78632534197; +78632530708 | G13: http://rosz61.ru | H13: ГБУ РО "Ростовоблстройзаказчик" | I13: ГБУ РО "РОСТОВОБЛСТРОЙЗАКАЗЧИК" | J13: 6163099188 | K13: 1096195004014 | L13: +7 (863) 253-07-08 | M13: 344050, РОССИЯ, г.Ростов-на-Дону, ул.Социалистическая, 112 | N13: Директор Мищенко Сергей Николаевич | O13: прекращено 06.06.2017 | P13: 159 | Q13: 40227 | T13: 40100 | U13: Государственное бюджетное учреждение Государственное бюджетное учреждение Ростовской области "Ростовоблстройзаказчик" | V13: файл 2, № 556 | W13: Checko | X13: ЕГРЮЛ/ЕГРИП (Checko): «Действует» | Y13: Checko API (ЕГРЮЛ/ЕГРИП), https://checko.ru/search?query=6163099188 | AA13: Открыть
A14: 13 | B14: Действует | C14: Действует | E14: zao.amus@mail.ru | F14: +78613763396; +78613753421; +78613753139; +78613753396 | G14: http://amus.com.ru | H14: ЗАО "АМУС" | I14: ЗАО "АМУС" | J14: 2302008401 | K14: 1022300635862 | L14: +7 (861) 375-33-96 | M14: 352922, РОССИЯ, г.Армавир, ул.Кропоткина, 1 | N14: Инженер по подготовке производства Митякин Анатолий Анатольевич | O14: нет данных | P14: 65 | Q14: 40213 | S14: 0 | T14: 37565 | U14: Закрытое акционерное общество "Армавирское монтажное управление специализированное" | V14: файл 1, № 101 | W14: Checko | X14: ЕГРЮЛ/ЕГРИП (Checko): «Действует» | Y14: Checko API (ЕГРЮЛ/ЕГРИП), https://checko.ru/search?query=2302008401 https://www.rusprofile.ru/id/1781599 https://focus.kontur.ru/entity?query=1022300635862 | AA14: Открыть
A15: 14 | B15: Действует | C15: Действует | E15: dvs@donvodservis.ru | F15: +78635450501 | H15: ЗАО "Водавтоматика" | I15: ЗАО "ВОДАВТОМАТИКА" | J15: 6141003559 | K15: 1026101846495 | L15: +7 (863) 545-83-83 | M15: 346880, РОССИЯ, г.Батайск, ул.Фермерская, 27 | N15: Директор Желенков Александр Дмитриевич | O15: прекращено 20.10.2015 | P15: 49 | Q15: 40037 | T15: 37614 | U15: Закрытое акционерное общество "Водавтоматика" | V15: файл 2, № 579 | W15: Checko | X15: ЕГРЮЛ/ЕГРИП (Checko): «Действует» | Y15: Checko API (ЕГРЮЛ/ЕГРИП), https://checko.ru/search?query=6141003559 | AA15: Открыть
A16: 15 | B16: Действует | C16: Действует | E16: promstroiru@yandex.ru | F16: +79612935577 | H16: ЗАО "ГРАЖДАНПРОМСТРОЙ" | I16: АО "ГРАЖДАНПРОМСТРОЙ" | J16: 6164074299 | K16: 1026103264846 | L16: +7 (863) 280-05-12 | M16: 344022, РОССИЯ, г.Ростов-на-Дону, ул.Московская, 71, офис 22 | N16: Генеральный директор Афанасьев Виктор Иванович | O16: прекращено 16.02.2017 | P16: 36 | Q16: 39995 | T16: 37455 | U16: Закрытое акционерное общество "ГРАЖДАНПРОМСТРОЙ" | V16: файл 2, № 650 | W16: Checko | X16: ЕГРЮЛ/ЕГРИП (Checko): «Действует» | Y16: Checko API (ЕГРЮЛ/ЕГРИП), https://checko.ru/search?query=6164074299 | AA16: Открыть
A17: 16 | B17: Действует | C17: Действует | E17: pmk-18@mail.ru; pmk18buhg@mail.ru | F17: +78636552992; +78636573601; +78636572992 | H17: ЗАО "ПМК-18" | I17: ЗАО "ПМК-18" | J17: 6147006242 | K17: 1026102107921 | L17: +7 (863) 657-29-92 | M17: 347800, РОССИЯ, Ростовская область, г.Каменск-Шахтинский, ул.Халтурина, 40 | N17: Генеральный директор Ким Алексей Олегович | O17: член СРО | P17: 97 | Q17: 40227 | T17: 37571 | U17: Закрытое акционерное общество "ПМК-18" | V17: файл 2, № 668 | W17: Checko | X17: ЕГРЮЛ/ЕГРИП (Checko): «Действует» | Y17: Checko API (ЕГРЮЛ/ЕГРИП), https://checko.ru/search?query=6147006242 | AA17: Открыть
A18: 17 | B18: Действует | C18: Действует | E18: zao-elina@mail.ru; zao-eina@mail.ru; elina@yandex.ru | F18: +78632995593; +79085186184; +78632012526; +78632905668; +78632981362 | H18: ЗАО "ЭЛИНА" | I18: ЗАО "ЭЛИНА" | J18: 6165000878 | K18: 1026103714460 | L18: +7 (863) 290-56-67 | M18: 344065, РОССИЯ, г.Ростов-на-Дону, пр. Стачки, 200/2 | N18: Директор Жолобов Алексей Владимирович | O18: прекращено 31.03.2014 | P18: 161 | Q18: 39995 | T18: 37523 | U18: Закрытое акционерное общество "ЭЛИНА" | V18: файл 2, № 636 | W18: Checko | X18: ЕГРЮЛ/ЕГРИП (Checko): «Действует» | Y18: Checko API (ЕГРЮЛ/ЕГРИП), https://checko.ru/search?query=6165000878 | AA18: Открыть
A19: 18 | B19: Действует | C19: Действует | E19: utm@utmdon.ru; or@utmdon.ru | F19: +78632408704; +78632408262; +78632407081; +78464370920; +78632320246 | H19: ЗАО "Южтехмонтаж" | I19: ЗАО "ЮЖТЕХМОНТАЖ" | J19: 6164100492 | K19: 1026103270335 | L19: +7 (863) 240-82-62 | M19: 344007, РОССИЯ, Ростовская область, г.Ростов-на-Дону, ул.Социалистическая, 60 | N19: Генеральный директор Свитенко Виталий Васильевич | O19: член СРО | P19: 99 | Q19: 40161 | T19: 37512 | U19: Закрытое акционерное общество "Южтехмонтаж" | V19: файл 2, № 561 | W19: Checko | X19: ЕГРЮЛ/ЕГРИП (Checko): «Действует» | Y19: Checko API (ЕГРЮЛ/ЕГРИП), https://checko.ru/search?query=6164100492 | AA19: Открыть
A20: 19 | B20: Действует | C20: Действует | E20: avitikov.v@mail.ru | H20: ИП Авитиков Вадим Сукратович | I20: ИП Авитиков Вадим Сукратович | J20: 616617926902 | K20: 319619600162482 | L20: +7 (961) 422-71-11 | O20: член СРО | P20: 71 | Q20: 45015 | T20: 43691 | U20: Индивидуальный предприниматель Авитиков Вадим Сукратович | V20: файл 2, № 743 | W20: Checko | X20: ЕГРЮЛ/ЕГРИП (Checko): «Действует» | Y20: Checko API (ЕГРЮЛ/ЕГРИП), https://checko.ru/search?query=616617926902 | AA20: Открыть
A21: 20 | B21: Действует | C21: Действует | E21: aydinov.89@bk.ru | H21: ИП Айдинов Рустам Мейданалиевич | I21: ИП Айдинов Рустам Мейданалиевич | J21: 611804113030 | K21: 321619600009860 | L21: +7 (906) 324-44-49 | N21: Айдинов Рустам Мейданалиевич | O21: член СРО | P21: 65 | Q21: 44909 | R21: Решение Совета Союза "Строители Ростовской области" №794 от 13.12.2022 г. | S21: 100 000 | T21: 44222 | U21: Индивидуальный предприниматель Айдинов Рустам Мейданалиевич | V21: файл 1, № 199 | W21: Checko | X21: ЕГРЮЛ/ЕГРИП (Checko): «Действует» | Y21: Checko API (ЕГРЮЛ/ЕГРИП), https://checko.ru/search?query=611804113030 | AA21: Открыть
A22: 21 | B22: Действует | C22: Действует | E22: artprintbk@mail.ru | H22: ИП Амирханян Сергей Саркисович | I22: ИП Амирханян Сергей Саркисович | J22: 614208510755 | K22: 304614233100071 | L22: +7 (928) 612-33-32 | N22: Амирханян Сергей Саркисович | O22: прекращено | P22: 53 | Q22: 44589 | R22: Решение Совета Союза "Строители Ростовской области" №710 от 27.01.2022 г. | S22: 100 000 | T22: 37860 | U22: Индивидуальный предприниматель Амирханян Сергей Саркисович | V22: файл 1, № 147 | W22: Checko | X22: ЕГРЮЛ/ЕГРИП (Checko): «Действует» | Y22: Checko API (ЕГРЮЛ/ЕГРИП), https://checko.ru/search?query=614208510755 https://www.rusprofile.ru/ip/%D0%90%D0%9C%D0%98/33 | AA22: Открыть
A23: 22 | B23: Действует | C23: Действует | E23: edegar.arakelyan@yandex.ru | H23: ИП Аракелян Эдгар Артушович | I23: ИП Аракелян Эдгар Артушович | J23: 616118197242 | K23: 319619600051941 | L23: +7 (938) 127-40-74 | N23: Аракелян Эдгар Артушович | O23: член СРО | P23: 77 | Q23: 45161 | R23: Решение Совета Союза "Строители Ростовской области" №874 от 22.08.2023 г. | S23: 100 000 | T23: 43544 | U23: Индивидуальный предприниматель Аракелян Эдгар Артушович | V23: файл 1, № 104 | W23: Checko | X23: ЕГРЮЛ/ЕГРИП (Checko): «Действует» | Y23: Checko API (ЕГРЮЛ/ЕГРИП), https://checko.ru/search?query=616118197242 | AA23: Открыть
A24: 23 | B24: Действует | C24: Действует | E24: 79185074947@yandex.ru | H24: ИП Береза Инна Сергеевна | I24: ИП Береза Инна Сергеевна | J24: 616405031226 | K24: 321619600046962 | L24: +7 (928) 755-09-09 | N24: Не хочет говорить | O24: прекращено | P24: 35 | Q24: 44299 | R24: Решение Совета Союза "Строители Ростовской области" №620 от 13.04.2021 г. | S24: 100 000 | T24: 44265 | U24: Индивидуальный предприниматель Береза Инна Сергеевна | V24: файл 1, № 51 | W24: Checko | X24: ЕГРЮЛ/ЕГРИП (Checko): «Действует» | Y24: Checko API (ЕГРЮЛ/ЕГРИП), https://checko.ru/search?query=616405031226 | AA24: Открыть
A25: 24 | B25: Действует | C25: Действует | E25: ugstroisnab@bk.ru | H25: ИП Близнюков Валерий Герасимович | I25: ИП Близнюков Валерий Герасимович | J25: 615412848962 | K25: 307615420100062 | L25: +7 (928) 125-65-50 | N25: Близнюков Валерий Герасимович | O25: член СРО | P25: 63 | Q25: 44824 | R25: Решение Совета Союза "Строители Ростовской области" №768 от 19.09.2022 г. | S25: 100 000 | T25: 39283 | U25: Индивидуальный предприниматель Близнюков Валерий Герасимович | V25: файл 1, № 401 | W25: Checko | X25: ЕГРЮЛ/ЕГРИП (Checko): «Действует» | Y25: Checko API (ЕГРЮЛ/ЕГРИП), https://checko.ru/search?query=615412848962 https://www.rusprofile.ru/date-ip/2007-07-20 https://poisktenderov.ru/item/0158300020121000009/ | AA25: Открыть
A26: 25 | B26: Действует | C26: Действует | E26: sm-yug@bk.ru | H26: ИП Гайдаров Назим Мавлудович | I26: ИП Гайдаров Назим Мавлудович | J26: 610304355840 | K26: 318619600066333 | L26: +7 (903) 489-52-39 | N26: Гайдаров Назим Мавлудович | O26: прекращено | P26: 48 | Q26: 44469 | R26: Решение Совета Союза "Строители Ростовской области" №668 от 30.09.2021 г. | S26: 100 000 | T26: 43200 | U26: Индивидуальный предприниматель Гайдаров Назим Мавлудович | V26: файл 1, № 106 | W26: Checko | X26: ЕГРЮЛ/ЕГРИП (Checko): «Действует»; в ЕФРСБ сообщений: 4 (последнее: Сообщение о результатах проведения собрания кредиторов 13.07.2026) | Y26: Checko API (ЕГРЮЛ/ЕГРИП), https://checko.ru/search?query=610304355840 https://www.npsro.info/reestrsro/view?id=585 | AA26: Открыть
A27: 26 | B27: Действует | C27: Действует | E27: rnd.rus@bk.ru | H27: ИП Гальцев Роман Анатольевич | I27: ИП Гальцев Роман Анатольевич | J27: 615309318231 | K27: 322619600081231 | L27: +7 (928) 279-55-88 | O27: член СРО | P27: 62 | Q27: 44749 | T27: 44653 | U27: Индивидуальный предприниматель Гальцев Роман Анатольевич | V27: файл 2, № 872 | W27: Checko | X27: ЕГРЮЛ/ЕГРИП (Checko): «Действует» | Y27: Checko API (ЕГРЮЛ/ЕГРИП), https://checko.ru/search?query=615309318231 | AA27: Открыть
A28: 27 | B28: Действует | C28: Действует | E28: aladdin13@yandex.ru | H28: ИП Гончаров Александр Александрович | I28: ИП Гончаров Александр Александрович | J28: 616612899067 | K28: 316619600087149 | L28: +7 (908) 506-08-32 | O28: член СРО | P28: 28 | Q28: 43822 | T28: 42429 | U28: Индивидуальный предприниматель Гончаров Александр Александрович | V28: файл 2, № 606 | W28: Checko | X28: ЕГРЮЛ/ЕГРИП (Checko): «Действует» | Y28: Checko API (ЕГРЮЛ/ЕГРИП), https://checko.ru/search?query=616612899067 https://www.rusprofile.ru/ip/316619600087149 | AA28: Открыть
A29: 28 | B29: Действует | C29: Действует | E29: 79185145798@yandex.ru | H29: ИП Дрябо Виталий Владимирович | I29: ИП Дрябо Виталий Владимирович | J29: 616711518330 | K29: 313619508400056 | L29: +7 (918) 514-57-98 | O29: член СРО | P29: 68 | Q29: 44966 | T29: 41358 | U29: Индивидуальный предприниматель Дрябо Виталий Владимирович | V29: файл 2, № 569 | W29: Checko | X29: ЕГРЮЛ/ЕГРИП (Checko): «Действует» | Y29: Checko API (ЕГРЮЛ/ЕГРИП), https://checko.ru/search?query=616711518330 | AA29: Открыть
A30: 29 | B30: Действует | C30: Действует | E30: ruslan_ermishin@mail.ru | H30: ИП Ермишин Руслан Маратович | I30: ИП Ермишин Руслан Маратович | J30: 616712899832 | K30: 320619600054445 | L30: +7 (928) 123-65-30 | N30: Ермишин Руслан Маратович | O30: член СРО | P30: 82 | Q30: 45279 | R30: Решение Совета Союза "Строители Ростовской области" №913 от 18.12.2023 г. | S30: 100 000 | T30: 43942 | U30: Индивидуальный предприниматель Ермишин Руслан Маратович | V30: файл 1, № 433 | W30: Checko | X30: ЕГРЮЛ/ЕГРИП (Checko): «Действует» | Y30: Checko API (ЕГРЮЛ/ЕГРИП), https://checko.ru/search?query=616712899832 | AA30: Открыть
A31: 30 | B31: Действует | C31: Действует | E31: oks-novshah@mail.ru | H31: ИП Захаров Дмитрий Николаевич | I31: ИП Захаров Дмитрий Николаевич | J31: 615103968003 | K31: 320619600105676 | L31: +7 (908) 190-92-47 | O31: член СРО | P31: 32 | Q31: 44161 | T31: 44048 | U31: Индивидуальный предприниматель Захаров Дмитрий Николаевич | V31: файл 2, № 852 | W31: Checko | X31: ЕГРЮЛ/ЕГРИП (Checko): «Действует» | Y31: Checko API (ЕГРЮЛ/ЕГРИП), https://checko.ru/search?query=615103968003 https://npsro.info/member/2154 | AA31: Открыть
A32: 31 | B32: Действует | C32: Действует | E32: 4107147@mail.ru | H32: ИП Ильчук Татьяна Эдуардовна | I32: ИП Ильчук Татьяна Эдуардовна | J32: 232525732620 | K32: 320619600095439 | L32: +7 (918) 590-15-03 | N32: Ильчук Татьяна Эдуардовна | O32: член СРО | P32: 55 | Q32: 44672 | R32: Решение Совета Союза "Строители Ростовской области" №730 от 20.04.2022 г. | S32: 100 000 | T32: 44028 | U32: Индивидуальный предприниматель Ильчук Татьяна Эдуардовна | V32: файл 1, № 205 | W32: Checko | X32: ЕГРЮЛ/ЕГРИП (Checko): «Действует» | Y32: Checko API (ЕГРЮЛ/ЕГРИП), https://checko.ru/search?query=232525732620 | AA32: Открыть
A33: 32 | B33: Действует | C33: Действует | E33: avk-fermer@yandex.ru | H33: ИП Карпенко Анастасия Викторовна | I33: ИП Карпенко Анастасия Викторовна | J33: 262306955510 | K33: 314618120200086 | L33: +7 (863) 209-86-13 | N33: Карпенко Анастасия Викторовна | O33: нет данных | P33: 8 | Q33: 42199 | S33: 0 | T33: 41841 | U33: Индивидуальный предприниматель Карпенко Анастасия Викторовна | V33: файл 1, № 214 | W33: Checko | X33: ЕГРЮЛ/ЕГРИП (Checko): «Действует»; ОГРНИП сменился: в файле 314618120200086, сейчас 325265100049729 (новая регистрация) | Y33: Checko API (ЕГРЮЛ/ЕГРИП), https://checko.ru/search?query=262306955510 | AA33: Открыть
A34: 33 | B34: Действует | C34: Действует | E34: asbuo@yandex.ru | H34: ИП Ларцев Василий Васильевич | I34: ИП Ларцев Василий Васильевич | J34: 616500747080 | K34: 312616524000021 | L34: +7 (918) 565-65-44 | N34: Ларцев Василий Васильевич | O34: член СРО | P34: 51 | Q34: 44501 | R34: Решение Совета Союза "Строители Ростовской области" №683 от 01.11.2021 г. | S34: 100 000 | T34: 41148 | U34: Индивидуальный предприниматель Ларцев Василий Васильевич | V34: файл 1, № 112 | W34: Checko | X34: ЕГРЮЛ/ЕГРИП (Checko): «Действует» | Y34: Checko API (ЕГРЮЛ/ЕГРИП), https://checko.ru/search?query=616500747080 https://www.rusprofile.ru/person/larcev-vv-616500747080 | AA34: Открыть
A35: 34 | B35: Действует | C35: Действует | E35: yuexcentr@yandex.ru | H35: ИП Ляшенко Геннадий Николаевич | I35: ИП Ляшенко Геннадий Николаевич | J35: 616831688171 | K35: 306616802600030 | L35: +7 (863) 232-98-04 | O35: прекращено 26.04.2011 | P35: 3 | Q35: 40112 | T35: 39762 | U35: Индивидуальный предприниматель Ляшенко Геннадий Николаевич | V35: файл 2, № 746 | W35: Checko | X35: ЕГРЮЛ/ЕГРИП (Checko): «Действует» | Y35: Checko API (ЕГРЮЛ/ЕГРИП), https://checko.ru/search?query=616831688171 | AA35: Открыть
A36: 35 | B36: Действует | C36: Действует | E36: nina.vasilevna2012@yandex.ru | H36: ИП Мацаков Николай Васильевич | I36: ИП Мацаков Николай Васильевич | J36: 610100305016 | K36: 304610102200010 | L36: +7 (903) 43-44-539 | N36: Мацаков Николай Васильевич | O36: прекращено | P36: 36 | Q36: 44299 | R36: Решение Совета Союза "Строители Ростовской области" №620 от 13.04.2021 г. | S36: 100 000 | T36: 37495 | U36: Индивидуальный предприниматель Мацаков Николай Васильевич. | V36: файл 1, № 52 | W36: Checko | X36: ЕГРЮЛ/ЕГРИП (Checko): «Действует» | Y36: Checko API (ЕГРЮЛ/ЕГРИП), https://checko.ru/search?query=610100305016 https://romanovskaya.rabota.ru/company/4796355/ https://inndex.ru/ip/region-120/okved-41.2 | AA36: Открыть
A37: 36 | B37: Действует | C37: Действует | E37: medkowa2016@yandex.ru; sheplstw@gmail.com | H37: ИП Медкова Ирина Васильевна | I37: ИП Медкова Ирина Васильевна | J37: 614903048557 | K37: 318619600183972 | L37: +7 (914) 717-63-56 | O37: член СРО | P37: 49 | Q37: 44474 | T37: 43350 | U37: Индивидуальный предприниматель Медкова Ирина Васильевна | V37: файл 2, № 605 | W37: Checko | X37: ЕГРЮЛ/ЕГРИП (Checko): «Действует» | Y37: Checko API (ЕГРЮЛ/ЕГРИП), https://checko.ru/search?query=614903048557 https://www.npsro.info/reestrsro/view?id=31&Sanction_sort=info.desc&Auditplan_sort=state.desc https://companies.rbc.ru/alphabetical-catalog/individuals/m-e-d/21/ | AA37: Открыть
A38: 37 | B38: Действует | C38: Действует | E38: c20xe@ya.ru | H38: ИП Мезин Антон Геннадьевич | I38: ИП Мезин Антон Геннадьевич | J38: 616113517322 | K38: 319619600189121 | L38: +7 (928) 964-60-85 | N38: Мезин Антон Геннадьевич | O38: член СРО | P38: 30 | Q38: 44119 | R38: Решение Совета Союза "Строители Ростовской области" №582 от 15.10.2020 г. | S38: 100 000 | T38: 43734 | U38: Индивидуальный предприниматель Мезин Антон Геннадьевич | V38: файл 1, № 231 | W38: Checko | X38: ЕГРЮЛ/ЕГРИП (Checko): «Действует» | Y38: Checko API (ЕГРЮЛ/ЕГРИП), https://checko.ru/search?query=616113517322 | AA38: Открыть
A39: 38 | B39: Действует | C39: Действует | E39: sergej.libra@gmail.com | H39: ИП Мисюк Сергей Александрович | I39: ИП Мисюк Сергей Александрович | J39: 616600687420 | K39: 318619600092671 | L39: +7 (989) 711-99-18 | N39: Мисюк Сергей Александрович | O39: член СРО | P39: 84 | Q39: 45306 | R39: Решение Совета Союза "Строители Ростовской области" №921 от 12.01.2024 г. | S39: 100 000 | T39: 43238 | U39: Индивидуальный предприниматель Мисюк Сергей Александрович | V39: файл 1, № 327 | W39: Checko | X39: ЕГРЮЛ/ЕГРИП (Checko): «Действует» | Y39: Checko API (ЕГРЮЛ/ЕГРИП), https://checko.ru/search?query=616600687420 | AA39: Открыть
A40: 39 | B40: Действует | C40: Действует | E40: bonij66@mail.ru | H40: ИП Михай Диана Юрьевна | I40: ИП Михай Диана Юрьевна | J40: 615433323370 | K40: 318619600167161 | L40: +7 (950) 865-82-81 | O40: член СРО | P40: 52 | Q40: 44545 | T40: 43326 | U40: Индивидуальный предприниматель Михай Диана Юрьевна | V40: файл 2, № 908 | W40: Checko | X40: ЕГРЮЛ/ЕГРИП (Checko): «Действует» | Y40: Checko API (ЕГРЮЛ/ЕГРИП), https://checko.ru/search?query=615433323370 | AA40: Открыть
...
